<mujoco model="base">
  <compiler angle="radian" meshdir="meshes/"/>

  <option impratio="20" density="1.2" viscosity="2e-05" cone="elliptic"/>

  <size njmax="5000" nconmax="5000"/>

  <visual>
    <map znear="0.001"/>
  </visual>

  <asset>
    <texture type="skybox" colorspace="auto" builtin="gradient" rgb1="0.9 0.9 1" rgb2="0.2 0.3 0.4" width="256" height="1536"/>
    <texture type="2d" colorspace="linear" name="texplane" file="/home/sylvia/sylvia/bigai/03vla/LIBERO-Mem/libero-mem/libero/libero/assets/textures/gray_ceramic_tile.png"/>
    <texture type="cube" colorspace="linear" name="tex-table" file="/home/sylvia/sylvia/bigai/03vla/LIBERO-Mem/libero-mem/libero/libero/assets/textures/martin_novak_wood_table.png"/>
    <texture type="cube" colorspace="linear" name="tex-table-legs" file="/home/sylvia/sylvia/bigai/03vla/LIBERO-Mem/libero-mem/libero/libero/assets/textures/martin_novak_wood_table.png"/>
    <texture type="2d" colorspace="linear" name="tex-wall" file="/home/sylvia/sylvia/bigai/03vla/LIBERO-Mem/libero-mem/libero/libero/assets/textures/yellow_linen_wall_texture.png"/>
    <texture type="cube" colorspace="auto" name="textable" builtin="flat" rgb2="0.8 0.8 0.8" width="512" height="3072"/>
    <texture type="2d" colorspace="linear" name="tex-kitchen_background" file="/home/sylvia/sylvia/bigai/03vla/LIBERO-Mem/libero-mem/libero/libero/assets/scenes/kitchen_background/kitchen_background.png"/>
    <texture type="2d" colorspace="linear" name="tex-kitchen_background_pot" file="/home/sylvia/sylvia/bigai/03vla/LIBERO-Mem/libero-mem/libero/libero/assets/scenes/kitchen_background_pot/kitchen_background_pot.png"/>
    <texture type="2d" colorspace="linear" name="tex-kitchen_background_stove" file="/home/sylvia/sylvia/bigai/03vla/LIBERO-Mem/libero-mem/libero/libero/assets/scenes/kitchen_background_stove/kitchen_background_stove.png"/>
    <texture type="2d" colorspace="linear" name="tex-kitchen_background_fridge" file="/home/sylvia/sylvia/bigai/03vla/LIBERO-Mem/libero-mem/libero/libero/assets/scenes/fridge/metal.png"/>
    <texture type="2d" colorspace="linear" name="akita_black_bowl_1_tex-akita_black_bowl" file="/home/sylvia/sylvia/bigai/03vla/LIBERO-Mem/libero-mem/libero/libero/assets/stable_scanned_objects/akita_black_bowl/texture.png"/>
    <texture type="2d" colorspace="linear" name="wine_bottle_1_tex-wine_bottle_red_logo" file="/home/sylvia/sylvia/bigai/03vla/LIBERO-Mem/libero-mem/libero/libero/assets/turbosquid_objects/wine_bottle/label_wine.png"/>
    <texture type="2d" colorspace="linear" name="wine_bottle_1_tex-wine_bottle_red_cork" file="/home/sylvia/sylvia/bigai/03vla/LIBERO-Mem/libero-mem/libero/libero/assets/turbosquid_objects/wine_bottle/cork_texture.png"/>
    <texture type="2d" colorspace="linear" name="plate_1_tex-model" file="/home/sylvia/sylvia/bigai/03vla/LIBERO-Mem/libero-mem/libero/libero/assets/stable_scanned_objects/plate/texture.png"/>
    <texture type="2d" colorspace="linear" name="plate_2_tex-model" file="/home/sylvia/sylvia/bigai/03vla/LIBERO-Mem/libero-mem/libero/libero/assets/stable_scanned_objects/plate/texture.png"/>
    <texture type="2d" colorspace="linear" name="plate_3_tex-model" file="/home/sylvia/sylvia/bigai/03vla/LIBERO-Mem/libero-mem/libero/libero/assets/stable_scanned_objects/plate/texture.png"/>
    <texture type="2d" colorspace="linear" name="wooden_cabinet_1_tex-wooden_cabinet" file="/home/sylvia/sylvia/bigai/03vla/LIBERO-Mem/libero-mem/libero/libero/assets/articulated_objects/wooden_cabinet/dark_fine_wood.png"/>
    <texture type="2d" colorspace="linear" name="wooden_cabinet_1_tex-wooden_cabinet_base" file="/home/sylvia/sylvia/bigai/03vla/LIBERO-Mem/libero-mem/libero/libero/assets/articulated_objects/wooden_cabinet/dark_fine_wood.png"/>
    <texture type="2d" colorspace="linear" name="wooden_cabinet_1_tex-wooden_cabinet_handle" file="/home/sylvia/sylvia/bigai/03vla/LIBERO-Mem/libero-mem/libero/libero/assets/articulated_objects/wooden_cabinet/metal.png"/>
    <material name="floorplane" texture="texplane" texuniform="true" texrepeat="3 3" specular="0" shininess="0"/>
    <material name="table_texture" texture="tex-table" specular="0.2" shininess="0"/>
    <material name="table_legs" texture="tex-table-legs" shininess="0.8" reflectance="0.8"/>
    <material name="walls_mat" texture="tex-wall" texuniform="true" texrepeat="3 3" specular="0.8" shininess="0.3"/>
    <material name="table_mat" texture="textable"/>
    <material name="kitchen_background" texture="tex-kitchen_background" reflectance="0.5"/>
    <material name="kitchen_background_pot" texture="tex-kitchen_background_pot" reflectance="0.5"/>
    <material name="kitchen_background_hot_pot" reflectance="0.5" rgba="0.4 0.4 0.4 1"/>
    <material name="kitchen_background_stove" texture="tex-kitchen_background_stove" reflectance="0.5"/>
    <material name="kitchen_background_fridge" texture="tex-kitchen_background_fridge" reflectance="0.9"/>
    <material name="robot0_Face636_001" shininess="0.45" rgba="0.901961 0.921569 0.929412 1"/>
    <material name="robot0_Part__Feature017_001" shininess="0.45"/>
    <material name="robot0_Part__Feature018_001" shininess="0.45"/>
    <material name="robot0_Part__Feature019_001" shininess="0.45"/>
    <material name="robot0_Part__Feature022_001" shininess="0.45" rgba="0.901961 0.921569 0.929412 1"/>
    <material name="robot0_Part__Feature023_001" shininess="0.45" rgba="0.25098 0.25098 0.25098 1"/>
    <material name="robot0_Shell001_001" shininess="0.45" rgba="0.25098 0.25098 0.25098 1"/>
    <material name="robot0_Shell002_001" shininess="0.45" rgba="0.901961 0.921569 0.929412 1"/>
    <material name="robot0_Shell003_001" shininess="0.45" rgba="0.901961 0.921569 0.929412 1"/>
    <material name="robot0_Shell009_001" shininess="0.45" rgba="0.25098 0.25098 0.25098 1"/>
    <material name="robot0_Shell010_001" shininess="0.45" rgba="0.901961 0.921569 0.929412 1"/>
    <material name="robot0_Shell_001" shininess="0.45" rgba="0.25098 0.25098 0.25098 1"/>
    <material name="robot0_Part__Feature_001" shininess="0.45"/>
    <material name="robot0_Part__Feature024" shininess="0.45"/>
    <material name="robot0_Part__Feature001_010_001_002" shininess="0.45"/>
    <material name="robot0_Part__Feature002_007_001_002" shininess="0.45"/>
    <material name="robot0_Part__Feature003_004_001_002" shininess="0.45"/>
    <material name="robot0_Part__Feature_001_001_001_002" shininess="0.45" rgba="0.25098 0.25098 0.25098 1"/>
    <material name="robot0_Part__Feature001_001_003_001" shininess="0.45"/>
    <material name="robot0_Part__Feature002_001_003_001" shininess="0.45" rgba="0.25098 0.25098 0.25098 1"/>
    <material name="robot0_Part__Feature003_001_003_001" shininess="0.45"/>
    <material name="robot0_Part__Feature_002_003_001" shininess="0.45"/>
    <material name="robot0_Part__Feature_002_004_003" shininess="0.45"/>
    <material name="robot0_Shell001_001_001_003" shininess="0.45" rgba="0.25 0.25 0.25 1"/>
    <material name="robot0_Shell_001_001_003" shininess="0.45"/>
    <material name="robot0_Face064_002_001_002_001" shininess="0.45" rgba="1 0 0 1"/>
    <material name="robot0_Face065_002_001_002_001" shininess="0.45" rgba="0 1 0 1"/>
    <material name="robot0_Face374_002_001_002_001" shininess="0.45"/>
    <material name="robot0_Face539_002_001_002_001" shininess="0.45" rgba="0.25098 0.25098 0.25098 1"/>
    <material name="robot0_Part__Feature001_009_001_002_001" shininess="0.45" rgba="0.25098 0.25098 0.25098 1"/>
    <material name="robot0_Part__Feature002_006_001_002_001" shininess="0.45" rgba="0.25098 0.25098 0.25098 1"/>
    <material name="robot0_Shell002_002_001_002_001" shininess="0.45"/>
    <material name="robot0_Shell003_002_001_002_001" shininess="0.45"/>
    <material name="robot0_Shell004_001_001_002_001" shininess="0.45"/>
    <material name="robot0_Shell005_001_001_002_001" shininess="0.45"/>
    <material name="robot0_Shell006_003_002_001" shininess="0.45" rgba="0.901961 0.921569 0.929412 1"/>
    <material name="robot0_Shell007_002_002_001" shininess="0.45" rgba="0.25 0.25 0.25 1"/>
    <material name="robot0_Shell011_002_002_001" shininess="0.45"/>
    <material name="robot0_Shell012_002_002_001" shininess="0.45"/>
    <material name="robot0_Shell_003_001_002_001" shininess="0.45" rgba="0.25098 0.25098 0.25098 1"/>
    <material name="robot0_Union001_001_001_002_001" shininess="0.45" rgba="0.039216 0.541176 0.780392 1"/>
    <material name="robot0_Union_001_001_002_001" shininess="0.45" rgba="0.039216 0.541176 0.780392 1"/>
    <material name="robot0_Part__Mirroring001_004_002" shininess="0.45" rgba="0.25098 0.25098 0.25098 1"/>
    <material name="robot0_Part__Mirroring002_004_001" shininess="0.45" rgba="0.25098 0.25098 0.25098 1"/>
    <material name="robot0_Part__Mirroring003_004_001" shininess="0.45" rgba="0.25098 0.25098 0.25098 1"/>
    <material name="robot0_Part__Mirroring004_004_002" shininess="0.45"/>
    <material name="robot0_Part__Mirroring005_004_001" shininess="0.45" rgba="0.25098 0.25098 0.25098 1"/>
    <material name="robot0_Part__Mirroring006_004_001" shininess="0.45" rgba="0.25098 0.25098 0.25098 1"/>
    <material name="robot0_Part__Mirroring007_004_001" shininess="0.45" rgba="0.25098 0.25098 0.25098 1"/>
    <material name="robot0_Part__Mirroring_004_001" shininess="0.45" rgba="0.898039 0.917647 0.929412 1"/>
    <material name="akita_black_bowl_1_akita_black_bowl" texture="akita_black_bowl_1_tex-akita_black_bowl" reflectance="0.5"/>
    <material name="wine_bottle_1_wine_bottle_red_logo" texture="wine_bottle_1_tex-wine_bottle_red_logo" reflectance="0.5"/>
    <material name="wine_bottle_1_wine_bottle_red_cork" texture="wine_bottle_1_tex-wine_bottle_red_cork" reflectance="0.5"/>
    <material name="wine_bottle_1_wine_bottle_red_main" reflectance="0.5" rgba="0.004 0.036 0.002 1"/>
    <material name="plate_1_model" texture="plate_1_tex-model" reflectance="0.5"/>
    <material name="plate_2_model" texture="plate_2_tex-model" reflectance="0.5"/>
    <material name="plate_3_model" texture="plate_3_tex-model" reflectance="0.5"/>
    <material name="wooden_cabinet_1_wooden_cabinet_top" texture="wooden_cabinet_1_tex-wooden_cabinet" reflectance="0.5"/>
    <material name="wooden_cabinet_1_wooden_cabinet_base" texture="wooden_cabinet_1_tex-wooden_cabinet_base" reflectance="0.5"/>
    <material name="wooden_cabinet_1_wooden_cabinet_top_handle" texture="wooden_cabinet_1_tex-wooden_cabinet_handle" reflectance="0.5"/>
    <material name="wooden_cabinet_1_wooden_cabinet_middle" texture="wooden_cabinet_1_tex-wooden_cabinet" reflectance="0.5"/>
    <material name="wooden_cabinet_1_wooden_cabinet_middle_handle" texture="wooden_cabinet_1_tex-wooden_cabinet_handle" reflectance="0.5"/>
    <material name="wooden_cabinet_1_wooden_cabinet_bottom" texture="wooden_cabinet_1_tex-wooden_cabinet" reflectance="0.5"/>
    <material name="wooden_cabinet_1_wooden_cabinet_bottom_handle" texture="wooden_cabinet_1_tex-wooden_cabinet_handle" reflectance="0.5"/>
    <mesh name="kitchen_background_vis" file="/home/sylvia/sylvia/bigai/03vla/LIBERO-Mem/libero-mem/libero/libero/assets/scenes/kitchen_background/visual/kitchen_background_vis.msh" scale="0.01 0.01 0.01"/>
    <mesh name="kitchen_background_pot_vis" file="/home/sylvia/sylvia/bigai/03vla/LIBERO-Mem/libero-mem/libero/libero/assets/scenes/kitchen_background_pot/visual/kitchen_background_pot_vis.msh" scale="0.01 0.01 0.01"/>
    <mesh name="kitchen_background_hot_pot_vis" file="/home/sylvia/sylvia/bigai/03vla/LIBERO-Mem/libero-mem/libero/libero/assets/scenes/kitchen_background_hot_pot/visual/kitchen_background_hot_pot_vis.msh" scale="0.01 0.01 0.01"/>
    <mesh name="kitchen_background_stove_vis" file="/home/sylvia/sylvia/bigai/03vla/LIBERO-Mem/libero-mem/libero/libero/assets/scenes/kitchen_background_stove/visual/kitchen_background_stove_vis.msh" scale="0.01 0.01 0.01"/>
    <mesh name="kitchen_background_fridge_vis" file="/home/sylvia/sylvia/bigai/03vla/LIBERO-Mem/libero-mem/libero/libero/assets/scenes/fridge/visual/fridge_vis.msh" scale="0.01 0.01 0.01"/>
    <mesh name="robot0_link0" file="/home/sylvia/sylvia/bigai/03vla/LIBERO-Mem/libero-mem/thirdparty/robosuite/robosuite/models/assets/robots/panda/meshes/link0.stl"/>
    <mesh name="robot0_link1" file="/home/sylvia/sylvia/bigai/03vla/LIBERO-Mem/libero-mem/thirdparty/robosuite/robosuite/models/assets/robots/panda/meshes/link1.stl"/>
    <mesh name="robot0_link2" file="/home/sylvia/sylvia/bigai/03vla/LIBERO-Mem/libero-mem/thirdparty/robosuite/robosuite/models/assets/robots/panda/meshes/link2.stl"/>
    <mesh name="robot0_link3" file="/home/sylvia/sylvia/bigai/03vla/LIBERO-Mem/libero-mem/thirdparty/robosuite/robosuite/models/assets/robots/panda/meshes/link3.stl"/>
    <mesh name="robot0_link4" file="/home/sylvia/sylvia/bigai/03vla/LIBERO-Mem/libero-mem/thirdparty/robosuite/robosuite/models/assets/robots/panda/meshes/link4.stl"/>
    <mesh name="robot0_link5" file="/home/sylvia/sylvia/bigai/03vla/LIBERO-Mem/libero-mem/thirdparty/robosuite/robosuite/models/assets/robots/panda/meshes/link5.stl"/>
    <mesh name="robot0_link6" file="/home/sylvia/sylvia/bigai/03vla/LIBERO-Mem/libero-mem/thirdparty/robosuite/robosuite/models/assets/robots/panda/meshes/link6.stl"/>
    <mesh name="robot0_link7" file="/home/sylvia/sylvia/bigai/03vla/LIBERO-Mem/libero-mem/thirdparty/robosuite/robosuite/models/assets/robots/panda/meshes/link7.stl"/>
    <mesh name="robot0_link0_vis_0" file="/home/sylvia/sylvia/bigai/03vla/LIBERO-Mem/libero-mem/thirdparty/robosuite/robosuite/models/assets/robots/panda/obj_meshes/link0_vis/link0_vis_0.obj"/>
    <mesh name="robot0_link0_vis_1" file="/home/sylvia/sylvia/bigai/03vla/LIBERO-Mem/libero-mem/thirdparty/robosuite/robosuite/models/assets/robots/panda/obj_meshes/link0_vis/link0_vis_1.obj"/>
    <mesh name="robot0_link0_vis_2" file="/home/sylvia/sylvia/bigai/03vla/LIBERO-Mem/libero-mem/thirdparty/robosuite/robosuite/models/assets/robots/panda/obj_meshes/link0_vis/link0_vis_2.obj"/>
    <mesh name="robot0_link0_vis_3" file="/home/sylvia/sylvia/bigai/03vla/LIBERO-Mem/libero-mem/thirdparty/robosuite/robosuite/models/assets/robots/panda/obj_meshes/link0_vis/link0_vis_3.obj"/>
    <mesh name="robot0_link0_vis_4" file="/home/sylvia/sylvia/bigai/03vla/LIBERO-Mem/libero-mem/thirdparty/robosuite/robosuite/models/assets/robots/panda/obj_meshes/link0_vis/link0_vis_4.obj"/>
    <mesh name="robot0_link0_vis_5" file="/home/sylvia/sylvia/bigai/03vla/LIBERO-Mem/libero-mem/thirdparty/robosuite/robosuite/models/assets/robots/panda/obj_meshes/link0_vis/link0_vis_5.obj"/>
    <mesh name="robot0_link0_vis_6" file="/home/sylvia/sylvia/bigai/03vla/LIBERO-Mem/libero-mem/thirdparty/robosuite/robosuite/models/assets/robots/panda/obj_meshes/link0_vis/link0_vis_6.obj"/>
    <mesh name="robot0_link0_vis_7" file="/home/sylvia/sylvia/bigai/03vla/LIBERO-Mem/libero-mem/thirdparty/robosuite/robosuite/models/assets/robots/panda/obj_meshes/link0_vis/link0_vis_7.obj"/>
    <mesh name="robot0_link0_vis_8" file="/home/sylvia/sylvia/bigai/03vla/LIBERO-Mem/libero-mem/thirdparty/robosuite/robosuite/models/assets/robots/panda/obj_meshes/link0_vis/link0_vis_8.obj"/>
    <mesh name="robot0_link0_vis_9" file="/home/sylvia/sylvia/bigai/03vla/LIBERO-Mem/libero-mem/thirdparty/robosuite/robosuite/models/assets/robots/panda/obj_meshes/link0_vis/link0_vis_9.obj"/>
    <mesh name="robot0_link0_vis_10" file="/home/sylvia/sylvia/bigai/03vla/LIBERO-Mem/libero-mem/thirdparty/robosuite/robosuite/models/assets/robots/panda/obj_meshes/link0_vis/link0_vis_10.obj"/>
    <mesh name="robot0_link0_vis_11" file="/home/sylvia/sylvia/bigai/03vla/LIBERO-Mem/libero-mem/thirdparty/robosuite/robosuite/models/assets/robots/panda/obj_meshes/link0_vis/link0_vis_11.obj"/>
    <mesh name="robot0_link1_vis" file="/home/sylvia/sylvia/bigai/03vla/LIBERO-Mem/libero-mem/thirdparty/robosuite/robosuite/models/assets/robots/panda/obj_meshes/link1_vis/link1_vis.obj"/>
    <mesh name="robot0_link2_vis" file="/home/sylvia/sylvia/bigai/03vla/LIBERO-Mem/libero-mem/thirdparty/robosuite/robosuite/models/assets/robots/panda/obj_meshes/link2_vis/link2_vis.obj"/>
    <mesh name="robot0_link3_vis_0" file="/home/sylvia/sylvia/bigai/03vla/LIBERO-Mem/libero-mem/thirdparty/robosuite/robosuite/models/assets/robots/panda/obj_meshes/link3_vis/link3_vis_0.obj"/>
    <mesh name="robot0_link3_vis_1" file="/home/sylvia/sylvia/bigai/03vla/LIBERO-Mem/libero-mem/thirdparty/robosuite/robosuite/models/assets/robots/panda/obj_meshes/link3_vis/link3_vis_1.obj"/>
    <mesh name="robot0_link3_vis_2" file="/home/sylvia/sylvia/bigai/03vla/LIBERO-Mem/libero-mem/thirdparty/robosuite/robosuite/models/assets/robots/panda/obj_meshes/link3_vis/link3_vis_2.obj"/>
    <mesh name="robot0_link3_vis_3" file="/home/sylvia/sylvia/bigai/03vla/LIBERO-Mem/libero-mem/thirdparty/robosuite/robosuite/models/assets/robots/panda/obj_meshes/link3_vis/link3_vis_3.obj"/>
    <mesh name="robot0_link4_vis_0" file="/home/sylvia/sylvia/bigai/03vla/LIBERO-Mem/libero-mem/thirdparty/robosuite/robosuite/models/assets/robots/panda/obj_meshes/link4_vis/link4_vis_0.obj"/>
    <mesh name="robot0_link4_vis_1" file="/home/sylvia/sylvia/bigai/03vla/LIBERO-Mem/libero-mem/thirdparty/robosuite/robosuite/models/assets/robots/panda/obj_meshes/link4_vis/link4_vis_1.obj"/>
    <mesh name="robot0_link4_vis_2" file="/home/sylvia/sylvia/bigai/03vla/LIBERO-Mem/libero-mem/thirdparty/robosuite/robosuite/models/assets/robots/panda/obj_meshes/link4_vis/link4_vis_2.obj"/>
    <mesh name="robot0_link4_vis_3" file="/home/sylvia/sylvia/bigai/03vla/LIBERO-Mem/libero-mem/thirdparty/robosuite/robosuite/models/assets/robots/panda/obj_meshes/link4_vis/link4_vis_3.obj"/>
    <mesh name="robot0_link5_vis_0" file="/home/sylvia/sylvia/bigai/03vla/LIBERO-Mem/libero-mem/thirdparty/robosuite/robosuite/models/assets/robots/panda/obj_meshes/link5_vis/link5_vis_0.obj"/>
    <mesh name="robot0_link5_vis_1" file="/home/sylvia/sylvia/bigai/03vla/LIBERO-Mem/libero-mem/thirdparty/robosuite/robosuite/models/assets/robots/panda/obj_meshes/link5_vis/link5_vis_1.obj"/>
    <mesh name="robot0_link5_vis_2" file="/home/sylvia/sylvia/bigai/03vla/LIBERO-Mem/libero-mem/thirdparty/robosuite/robosuite/models/assets/robots/panda/obj_meshes/link5_vis/link5_vis_2.obj"/>
    <mesh name="robot0_link6_vis_0" file="/home/sylvia/sylvia/bigai/03vla/LIBERO-Mem/libero-mem/thirdparty/robosuite/robosuite/models/assets/robots/panda/obj_meshes/link6_vis/link6_vis_0.obj"/>
    <mesh name="robot0_link6_vis_1" file="/home/sylvia/sylvia/bigai/03vla/LIBERO-Mem/libero-mem/thirdparty/robosuite/robosuite/models/assets/robots/panda/obj_meshes/link6_vis/link6_vis_1.obj"/>
    <mesh name="robot0_link6_vis_2" file="/home/sylvia/sylvia/bigai/03vla/LIBERO-Mem/libero-mem/thirdparty/robosuite/robosuite/models/assets/robots/panda/obj_meshes/link6_vis/link6_vis_2.obj"/>
    <mesh name="robot0_link6_vis_3" file="/home/sylvia/sylvia/bigai/03vla/LIBERO-Mem/libero-mem/thirdparty/robosuite/robosuite/models/assets/robots/panda/obj_meshes/link6_vis/link6_vis_3.obj"/>
    <mesh name="robot0_link6_vis_4" file="/home/sylvia/sylvia/bigai/03vla/LIBERO-Mem/libero-mem/thirdparty/robosuite/robosuite/models/assets/robots/panda/obj_meshes/link6_vis/link6_vis_4.obj"/>
    <mesh name="robot0_link6_vis_5" file="/home/sylvia/sylvia/bigai/03vla/LIBERO-Mem/libero-mem/thirdparty/robosuite/robosuite/models/assets/robots/panda/obj_meshes/link6_vis/link6_vis_5.obj"/>
    <mesh name="robot0_link6_vis_6" file="/home/sylvia/sylvia/bigai/03vla/LIBERO-Mem/libero-mem/thirdparty/robosuite/robosuite/models/assets/robots/panda/obj_meshes/link6_vis/link6_vis_6.obj"/>
    <mesh name="robot0_link6_vis_7" file="/home/sylvia/sylvia/bigai/03vla/LIBERO-Mem/libero-mem/thirdparty/robosuite/robosuite/models/assets/robots/panda/obj_meshes/link6_vis/link6_vis_7.obj"/>
    <mesh name="robot0_link6_vis_8" file="/home/sylvia/sylvia/bigai/03vla/LIBERO-Mem/libero-mem/thirdparty/robosuite/robosuite/models/assets/robots/panda/obj_meshes/link6_vis/link6_vis_8.obj"/>
    <mesh name="robot0_link6_vis_9" file="/home/sylvia/sylvia/bigai/03vla/LIBERO-Mem/libero-mem/thirdparty/robosuite/robosuite/models/assets/robots/panda/obj_meshes/link6_vis/link6_vis_9.obj"/>
    <mesh name="robot0_link6_vis_10" file="/home/sylvia/sylvia/bigai/03vla/LIBERO-Mem/libero-mem/thirdparty/robosuite/robosuite/models/assets/robots/panda/obj_meshes/link6_vis/link6_vis_10.obj"/>
    <mesh name="robot0_link6_vis_11" file="/home/sylvia/sylvia/bigai/03vla/LIBERO-Mem/libero-mem/thirdparty/robosuite/robosuite/models/assets/robots/panda/obj_meshes/link6_vis/link6_vis_11.obj"/>
    <mesh name="robot0_link6_vis_12" file="/home/sylvia/sylvia/bigai/03vla/LIBERO-Mem/libero-mem/thirdparty/robosuite/robosuite/models/assets/robots/panda/obj_meshes/link6_vis/link6_vis_12.obj"/>
    <mesh name="robot0_link6_vis_13" file="/home/sylvia/sylvia/bigai/03vla/LIBERO-Mem/libero-mem/thirdparty/robosuite/robosuite/models/assets/robots/panda/obj_meshes/link6_vis/link6_vis_13.obj"/>
    <mesh name="robot0_link6_vis_14" file="/home/sylvia/sylvia/bigai/03vla/LIBERO-Mem/libero-mem/thirdparty/robosuite/robosuite/models/assets/robots/panda/obj_meshes/link6_vis/link6_vis_14.obj"/>
    <mesh name="robot0_link6_vis_15" file="/home/sylvia/sylvia/bigai/03vla/LIBERO-Mem/libero-mem/thirdparty/robosuite/robosuite/models/assets/robots/panda/obj_meshes/link6_vis/link6_vis_15.obj"/>
    <mesh name="robot0_link6_vis_16" file="/home/sylvia/sylvia/bigai/03vla/LIBERO-Mem/libero-mem/thirdparty/robosuite/robosuite/models/assets/robots/panda/obj_meshes/link6_vis/link6_vis_16.obj"/>
    <mesh name="robot0_link7_vis_0" file="/home/sylvia/sylvia/bigai/03vla/LIBERO-Mem/libero-mem/thirdparty/robosuite/robosuite/models/assets/robots/panda/obj_meshes/link7_vis/link7_vis_0.obj"/>
    <mesh name="robot0_link7_vis_1" file="/home/sylvia/sylvia/bigai/03vla/LIBERO-Mem/libero-mem/thirdparty/robosuite/robosuite/models/assets/robots/panda/obj_meshes/link7_vis/link7_vis_1.obj"/>
    <mesh name="robot0_link7_vis_2" file="/home/sylvia/sylvia/bigai/03vla/LIBERO-Mem/libero-mem/thirdparty/robosuite/robosuite/models/assets/robots/panda/obj_meshes/link7_vis/link7_vis_2.obj"/>
    <mesh name="robot0_link7_vis_3" file="/home/sylvia/sylvia/bigai/03vla/LIBERO-Mem/libero-mem/thirdparty/robosuite/robosuite/models/assets/robots/panda/obj_meshes/link7_vis/link7_vis_3.obj"/>
    <mesh name="robot0_link7_vis_4" file="/home/sylvia/sylvia/bigai/03vla/LIBERO-Mem/libero-mem/thirdparty/robosuite/robosuite/models/assets/robots/panda/obj_meshes/link7_vis/link7_vis_4.obj"/>
    <mesh name="robot0_link7_vis_5" file="/home/sylvia/sylvia/bigai/03vla/LIBERO-Mem/libero-mem/thirdparty/robosuite/robosuite/models/assets/robots/panda/obj_meshes/link7_vis/link7_vis_5.obj"/>
    <mesh name="robot0_link7_vis_6" file="/home/sylvia/sylvia/bigai/03vla/LIBERO-Mem/libero-mem/thirdparty/robosuite/robosuite/models/assets/robots/panda/obj_meshes/link7_vis/link7_vis_6.obj"/>
    <mesh name="robot0_link7_vis_7" file="/home/sylvia/sylvia/bigai/03vla/LIBERO-Mem/libero-mem/thirdparty/robosuite/robosuite/models/assets/robots/panda/obj_meshes/link7_vis/link7_vis_7.obj"/>
    <mesh name="mount0_pedestal" file="/home/sylvia/sylvia/bigai/03vla/LIBERO-Mem/libero-mem/thirdparty/robosuite/robosuite/models/assets/mounts/meshes/rethink_mount/pedestal.stl"/>
    <mesh name="gripper0_hand" file="/home/sylvia/sylvia/bigai/03vla/LIBERO-Mem/libero-mem/thirdparty/robosuite/robosuite/models/assets/grippers/meshes/panda_gripper/hand.stl"/>
    <mesh name="gripper0_hand_vis" file="/home/sylvia/sylvia/bigai/03vla/LIBERO-Mem/libero-mem/thirdparty/robosuite/robosuite/models/assets/grippers/meshes/panda_gripper/hand_vis.stl"/>
    <mesh name="gripper0_finger" file="/home/sylvia/sylvia/bigai/03vla/LIBERO-Mem/libero-mem/thirdparty/robosuite/robosuite/models/assets/grippers/meshes/panda_gripper/finger.stl"/>
    <mesh name="gripper0_finger_vis" file="/home/sylvia/sylvia/bigai/03vla/LIBERO-Mem/libero-mem/thirdparty/robosuite/robosuite/models/assets/grippers/meshes/panda_gripper/finger_vis.stl"/>
    <mesh name="gripper0_finger_vis2" file="/home/sylvia/sylvia/bigai/03vla/LIBERO-Mem/libero-mem/thirdparty/robosuite/robosuite/models/assets/grippers/meshes/panda_gripper/finger_longer.stl"/>
    <mesh name="akita_black_bowl_1_akita_black_bowl_vis" file="/home/sylvia/sylvia/bigai/03vla/LIBERO-Mem/libero-mem/libero/libero/assets/stable_scanned_objects/akita_black_bowl/visual/akita_black_bowl_vis.msh" scale="0.7 0.7 0.7"/>
    <mesh name="wine_bottle_1_wine_bottle_red_logo_vis" file="/home/sylvia/sylvia/bigai/03vla/LIBERO-Mem/libero-mem/libero/libero/assets/turbosquid_objects/wine_bottle/visual/wine_bottle_red_logo_vis.msh" scale="0.505 0.505 0.505"/>
    <mesh name="wine_bottle_1_wine_bottle_red_cork_vis" file="/home/sylvia/sylvia/bigai/03vla/LIBERO-Mem/libero-mem/libero/libero/assets/turbosquid_objects/wine_bottle/visual/wine_bottle_red_cork_vis.msh" scale="0.5 0.5 0.5"/>
    <mesh name="wine_bottle_1_wine_bottle_red_main_vis" file="/home/sylvia/sylvia/bigai/03vla/LIBERO-Mem/libero-mem/libero/libero/assets/turbosquid_objects/wine_bottle/visual/wine_bottle_red_main_vis.msh" scale="0.5 0.5 0.5"/>
    <mesh name="plate_1_model_vis" file="/home/sylvia/sylvia/bigai/03vla/LIBERO-Mem/libero-mem/libero/libero/assets/stable_scanned_objects/plate/visual/model_vis.msh" scale="0.5 0.5 0.5"/>
    <mesh name="plate_2_model_vis" file="/home/sylvia/sylvia/bigai/03vla/LIBERO-Mem/libero-mem/libero/libero/assets/stable_scanned_objects/plate/visual/model_vis.msh" scale="0.5 0.5 0.5"/>
    <mesh name="plate_3_model_vis" file="/home/sylvia/sylvia/bigai/03vla/LIBERO-Mem/libero-mem/libero/libero/assets/stable_scanned_objects/plate/visual/model_vis.msh" scale="0.5 0.5 0.5"/>
    <mesh name="wooden_cabinet_1_wooden_cabinet_top_vis" file="/home/sylvia/sylvia/bigai/03vla/LIBERO-Mem/libero-mem/libero/libero/assets/articulated_objects/wooden_cabinet/wooden_cabinet_top/visual/wooden_cabinet_top_vis.msh" scale="0.05 0.05 0.05"/>
    <mesh name="wooden_cabinet_1_wooden_cabinet_base_vis" file="/home/sylvia/sylvia/bigai/03vla/LIBERO-Mem/libero-mem/libero/libero/assets/articulated_objects/wooden_cabinet/wooden_cabinet_base/visual/wooden_cabinet_base_vis.msh" scale="0.05 0.05 0.05"/>
    <mesh name="wooden_cabinet_1_wooden_cabinet_top_handle_vis" file="/home/sylvia/sylvia/bigai/03vla/LIBERO-Mem/libero-mem/libero/libero/assets/articulated_objects/wooden_cabinet/wooden_cabinet_top_handle/visual/wooden_cabinet_top_handle_vis.msh" scale="0.05 0.05 0.05"/>
    <mesh name="wooden_cabinet_1_wooden_cabinet_middle_vis" file="/home/sylvia/sylvia/bigai/03vla/LIBERO-Mem/libero-mem/libero/libero/assets/articulated_objects/wooden_cabinet/wooden_cabinet_middle/visual/wooden_cabinet_middle_vis.msh" scale="0.05 0.05 0.05"/>
    <mesh name="wooden_cabinet_1_wooden_cabinet_middle_handle_vis" file="/home/sylvia/sylvia/bigai/03vla/LIBERO-Mem/libero-mem/libero/libero/assets/articulated_objects/wooden_cabinet/wooden_cabinet_middle_handle/visual/wooden_cabinet_middle_handle_vis.msh" scale="0.05 0.05 0.05"/>
    <mesh name="wooden_cabinet_1_wooden_cabinet_bottom_vis" file="/home/sylvia/sylvia/bigai/03vla/LIBERO-Mem/libero-mem/libero/libero/assets/articulated_objects/wooden_cabinet/wooden_cabinet_bottom/visual/wooden_cabinet_bottom_vis.msh" scale="0.05 0.05 0.05"/>
    <mesh name="wooden_cabinet_1_wooden_cabinet_bottom_handle_vis" file="/home/sylvia/sylvia/bigai/03vla/LIBERO-Mem/libero-mem/libero/libero/assets/articulated_objects/wooden_cabinet/wooden_cabinet_bottom_handle/visual/wooden_cabinet_bottom_handle_vis.msh" scale="0.05 0.05 0.05"/>
  </asset>

  <worldbody>
    <geom name="floor" size="3 3 0.125" type="plane" group="1" material="floorplane"/>
    <geom pos="-1.65 0 0.9" quat="0 0 0 1" type="mesh" contype="0" conaffinity="0" group="1" material="kitchen_background_stove" mesh="kitchen_background_stove_vis"/>
    <geom pos="-1.5 0.23 0.93" quat="0.316228 0 0 0.948683" type="mesh" contype="0" conaffinity="0" group="1" material="kitchen_background_hot_pot" mesh="kitchen_background_hot_pot_vis"/>
    <geom pos="-1.85 -0.85 0.9" quat="0 0 0 1" type="mesh" contype="0" conaffinity="0" group="1" material="kitchen_background_pot" mesh="kitchen_background_pot_vis"/>
    <geom pos="-1.75 -2.4 0" quat="0 0 0 1" type="mesh" contype="0" conaffinity="0" group="1" material="kitchen_background_fridge" mesh="kitchen_background_fridge_vis"/>
    <geom pos="-1.65 0 0" quat="0 0 0 1" type="mesh" contype="0" conaffinity="0" group="1" material="kitchen_background" mesh="kitchen_background_vis"/>
    <geom name="wall_left_visual" size="2.5 1.5 0.01" pos="0.5 3 1.5" quat="0.707107 0.707107 0 0" type="box" contype="0" conaffinity="0" group="1" material="walls_mat"/>
    <geom name="wall_right_visual" size="2.5 1.5 0.01" pos="0.5 -3 1.5" quat="0.707107 -0.707107 0 0" type="box" contype="0" conaffinity="0" group="1" material="walls_mat"/>
    <geom name="wall_rear_visual" size="3 1.5 0.01" pos="-2 0 1.5" quat="0.5 0.5 0.5 0.5" type="box" contype="0" conaffinity="0" group="1" material="walls_mat"/>
    <geom name="wall_front_visual" size="3 1.5 0.01" pos="3 0 1.5" quat="0.5 0.5 -0.5 -0.5" type="box" contype="0" conaffinity="0" group="1" material="walls_mat"/>
    <camera name="frontview" pos="1 0 1.48" quat="0.560842 0.430646 0.430646 0.560842"/>
    <camera name="birdview" pos="-0.2 0 3" quat="0.707107 0 0 0.707107"/>
    <camera name="agentview" pos="0.658613 0 1.61035" quat="0.638018 0.30485 0.30485 0.638018"/>
    <camera name="sideview" pos="-0.0565177 1.27612 1.48796" quat="0.00990507 0.00687796 0.591223 0.806418"/>
    <camera name="galleryview" pos="2.84455 2.12797 3.12862" quat="0.422614 0.233744 0.416469 0.770269"/>
    <camera name="paperview" pos="2.1 0.535 2.075" quat="0.512987 0.352991 0.442988 0.644983"/>
    <light name="light_kitchen" pos="-1.75 0 1.6" dir="0 0 -1" type="directional" castshadow="false" diffuse="0.8 0.8 0.8" specular="0.8 0.8 0.8"/>
    <light name="light1" pos="1 1 4" dir="0 -0.14834 -0.988936" castshadow="false" diffuse="0.8 0.8 0.8"/>
    <light name="light2" pos="-3 -3 4" dir="0 -0.14834 -0.988936" castshadow="false" diffuse="0.8 0.8 0.8"/>
    <body name="table" pos="0 0 0.875">
      <geom name="table_collision" size="0.5 0.6 0.025" type="box" rgba="0.5 0.5 0 1"/>
      <geom name="table_visual" size="0.5 0.6 0.025" type="box" contype="0" conaffinity="0" group="1" material="table_texture"/>
      <geom name="table_leg1_visual" size="0.025 0.4375" pos="0.4 0.5 -0.4375" type="cylinder" contype="0" conaffinity="0" group="1" material="table_legs"/>
      <geom name="table_leg2_visual" size="0.025 0.4375" pos="-0.4 0.5 -0.4375" type="cylinder" contype="0" conaffinity="0" group="1" material="table_legs"/>
      <geom name="table_leg3_visual" size="0.025 0.4375" pos="-0.4 -0.5 -0.4375" type="cylinder" contype="0" conaffinity="0" group="1" material="table_legs"/>
      <geom name="table_leg4_visual" size="0.025 0.4375" pos="0.4 -0.5 -0.4375" type="cylinder" contype="0" conaffinity="0" group="1" material="table_legs"/>
      <site name="table_top" pos="0 0 0.025" size="0.001" rgba="0 0 0 0"/>
      <site name="kitchen_table_wooden_cabinet_init_region" pos="0 -0.285 0" size="0.01 0.005 0.007" type="box" rgba="0 0 1 0"/>
      <site name="kitchen_table_plate_random_init_region_1" pos="-0.065 -0.08 0" size="0.185 0.07 0.007" type="box" rgba="0 0 1 0"/>
      <site name="kitchen_table_plate_random_init_region_2" pos="-0.065 0.125 0" size="0.185 0.075 0.007" type="box" rgba="0 0 1 0"/>
      <site name="kitchen_table_plate_random_init_region_3" pos="-0.065 0.025 0" size="0.185 0.175 0.007" type="box" rgba="0 0 1 0"/>
      <site name="kitchen_table_plate_random_init_region_4" pos="-0.065 0.025 0" size="0.185 0.175 0.007" type="box" rgba="0 0 1 0"/>
      <site name="kitchen_table_akita_black_bowl_front_init_region" pos="0.1 0.1125 0" size="0.025 0.0625 0.007" type="box" rgba="0 0 1 0"/>
      <site name="kitchen_table_akita_black_bowl_back_init_region" pos="-0.375 0.15 0" size="0.025 0.1 0.007" type="box" rgba="0 0 1 0"/>
    </body>
    <body name="robot0_base" pos="-0.66 0 0.912">
      <inertial pos="0 0 0" mass="0" diaginertia="0 0 0"/>
      <camera name="robot0_robotview" pos="1 0 0.4" quat="0.653098 0.271041 0.271041 0.653098"/>
      <body name="robot0_link0">
        <inertial pos="0 0 0.05" mass="4" diaginertia="0.4 0.4 0.4"/>
        <geom name="robot0_g0_vis" type="mesh" contype="0" conaffinity="0" group="1" material="robot0_Shell010_001" mesh="robot0_link0_vis_0"/>
        <geom name="robot0_g1_vis" type="mesh" contype="0" conaffinity="0" group="1" material="robot0_Shell009_001" mesh="robot0_link0_vis_1"/>
        <geom name="robot0_g2_vis" type="mesh" contype="0" conaffinity="0" group="1" material="robot0_Shell003_001" mesh="robot0_link0_vis_2"/>
        <geom name="robot0_g3_vis" type="mesh" contype="0" conaffinity="0" group="1" material="robot0_Shell_001" mesh="robot0_link0_vis_3"/>
        <geom name="robot0_g4_vis" type="mesh" contype="0" conaffinity="0" group="1" material="robot0_Shell002_001" mesh="robot0_link0_vis_4"/>
        <geom name="robot0_g5_vis" type="mesh" contype="0" conaffinity="0" group="1" material="robot0_Shell001_001" mesh="robot0_link0_vis_5"/>
        <geom name="robot0_g6_vis" type="mesh" contype="0" conaffinity="0" group="1" material="robot0_Face636_001" mesh="robot0_link0_vis_6"/>
        <geom name="robot0_g7_vis" type="mesh" contype="0" conaffinity="0" group="1" material="robot0_Part__Feature018_001" mesh="robot0_link0_vis_7"/>
        <geom name="robot0_g8_vis" type="mesh" contype="0" conaffinity="0" group="1" material="robot0_Part__Feature019_001" mesh="robot0_link0_vis_8"/>
        <geom name="robot0_g9_vis" type="mesh" contype="0" conaffinity="0" group="1" material="robot0_Part__Feature023_001" mesh="robot0_link0_vis_9"/>
        <geom name="robot0_g10_vis" type="mesh" contype="0" conaffinity="0" group="1" material="robot0_Part__Feature022_001" mesh="robot0_link0_vis_10"/>
        <geom name="robot0_g11_vis" type="mesh" contype="0" conaffinity="0" group="1" material="robot0_Part__Feature017_001" mesh="robot0_link0_vis_11"/>
        <geom name="robot0_link0_collision" type="mesh" rgba="0 0.5 0 1" mesh="robot0_link0"/>
        <body name="robot0_link1" pos="0 0 0.333">
          <inertial pos="0 0 -0.07" mass="3" diaginertia="0.3 0.3 0.3"/>
          <joint name="robot0_joint1" pos="0 0 0" axis="0 0 1" limited="true" range="-2.8973 2.8973" armature="5" damping="0.1" frictionloss="0.1"/>
          <geom name="robot0_g12_vis" type="mesh" contype="0" conaffinity="0" group="1" material="robot0_Part__Feature_001" mesh="robot0_link1_vis"/>
          <geom name="robot0_link1_collision" type="mesh" rgba="0 0.5 0 1" mesh="robot0_link1"/>
          <body name="robot0_link2" quat="0.707107 -0.707107 0 0">
            <inertial pos="0 -0.1 0" mass="3" diaginertia="0.3 0.3 0.3"/>
            <joint name="robot0_joint2" pos="0 0 0" axis="0 0 1" limited="true" range="-1.7628 1.7628" armature="2.5" damping="0.1" frictionloss="0.1"/>
            <geom name="robot0_g13_vis" type="mesh" contype="0" conaffinity="0" group="1" material="robot0_Part__Feature024" mesh="robot0_link2_vis"/>
            <geom name="robot0_link2_collision" type="mesh" rgba="0 0.5 0 1" mesh="robot0_link2"/>
            <body name="robot0_link3" pos="0 -0.316 0" quat="0.707107 0.707107 0 0">
              <inertial pos="0.04 0 -0.05" mass="2" diaginertia="0.2 0.2 0.2"/>
              <joint name="robot0_joint3" pos="0 0 0" axis="0 0 1" limited="true" range="-2.8973 2.8973" armature="1.66667" damping="0.1" frictionloss="0.1"/>
              <geom name="robot0_g14_vis" type="mesh" contype="0" conaffinity="0" group="1" material="robot0_Part__Feature003_004_001_002" mesh="robot0_link3_vis_0"/>
              <geom name="robot0_g15_vis" type="mesh" contype="0" conaffinity="0" group="1" material="robot0_Part__Feature002_007_001_002" mesh="robot0_link3_vis_1"/>
              <geom name="robot0_g16_vis" type="mesh" contype="0" conaffinity="0" group="1" material="robot0_Part__Feature001_010_001_002" mesh="robot0_link3_vis_2"/>
              <geom name="robot0_g17_vis" type="mesh" contype="0" conaffinity="0" group="1" material="robot0_Part__Feature_001_001_001_002" mesh="robot0_link3_vis_3"/>
              <geom name="robot0_link3_collision" type="mesh" rgba="0 0.5 0 1" mesh="robot0_link3"/>
              <body name="robot0_link4" pos="0.0825 0 0" quat="0.707107 0.707107 0 0">
                <inertial pos="-0.04 0.05 0" mass="2" diaginertia="0.2 0.2 0.2"/>
                <joint name="robot0_joint4" pos="0 0 0" axis="0 0 1" limited="true" range="-3.0718 -0.0698" armature="1.25" damping="0.1" frictionloss="0.1"/>
                <geom name="robot0_g18_vis" type="mesh" contype="0" conaffinity="0" group="1" material="robot0_Part__Feature001_001_003_001" mesh="robot0_link4_vis_0"/>
                <geom name="robot0_g19_vis" type="mesh" contype="0" conaffinity="0" group="1" material="robot0_Part__Feature003_001_003_001" mesh="robot0_link4_vis_1"/>
                <geom name="robot0_g20_vis" type="mesh" contype="0" conaffinity="0" group="1" material="robot0_Part__Feature002_001_003_001" mesh="robot0_link4_vis_2"/>
                <geom name="robot0_g21_vis" type="mesh" contype="0" conaffinity="0" group="1" material="robot0_Part__Feature_002_003_001" mesh="robot0_link4_vis_3"/>
                <geom name="robot0_link4_collision" type="mesh" rgba="0 0.5 0 1" mesh="robot0_link4"/>
                <body name="robot0_link5" pos="-0.0825 0.384 0" quat="0.707107 -0.707107 0 0">
                  <inertial pos="0 0 -0.15" mass="2" diaginertia="0.2 0.2 0.2"/>
                  <joint name="robot0_joint5" pos="0 0 0" axis="0 0 1" limited="true" range="-2.8973 2.8973" armature="1" damping="0.1" frictionloss="0.1"/>
                  <geom name="robot0_g22_vis" type="mesh" contype="0" conaffinity="0" group="1" material="robot0_Shell001_001_001_003" mesh="robot0_link5_vis_0"/>
                  <geom name="robot0_g23_vis" type="mesh" contype="0" conaffinity="0" group="1" material="robot0_Shell_001_001_003" mesh="robot0_link5_vis_1"/>
                  <geom name="robot0_g24_vis" type="mesh" contype="0" conaffinity="0" group="1" material="robot0_Part__Feature_002_004_003" mesh="robot0_link5_vis_2"/>
                  <geom name="robot0_link5_collision" type="mesh" rgba="0 0.5 0 1" mesh="robot0_link5"/>
                  <body name="robot0_link6" quat="0.707107 0.707107 0 0">
                    <inertial pos="0.06 0 0" mass="1.5" diaginertia="0.1 0.1 0.1"/>
                    <joint name="robot0_joint6" pos="0 0 0" axis="0 0 1" limited="true" range="-0.0175 3.7525" armature="0.833333" damping="0.01" frictionloss="0.1"/>
                    <geom name="robot0_g25_vis" type="mesh" contype="0" conaffinity="0" group="1" material="robot0_Shell006_003_002_001" mesh="robot0_link6_vis_0"/>
                    <geom name="robot0_g26_vis" type="mesh" contype="0" conaffinity="0" group="1" material="robot0_Shell011_002_002_001" mesh="robot0_link6_vis_1"/>
                    <geom name="robot0_g27_vis" type="mesh" contype="0" conaffinity="0" group="1" material="robot0_Shell007_002_002_001" mesh="robot0_link6_vis_2"/>
                    <geom name="robot0_g28_vis" type="mesh" contype="0" conaffinity="0" group="1" material="robot0_Shell005_001_001_002_001" mesh="robot0_link6_vis_3"/>
                    <geom name="robot0_g29_vis" type="mesh" contype="0" conaffinity="0" group="1" material="robot0_Shell004_001_001_002_001" mesh="robot0_link6_vis_4"/>
                    <geom name="robot0_g30_vis" type="mesh" contype="0" conaffinity="0" group="1" material="robot0_Shell003_002_001_002_001" mesh="robot0_link6_vis_5"/>
                    <geom name="robot0_g31_vis" type="mesh" contype="0" conaffinity="0" group="1" material="robot0_Shell002_002_001_002_001" mesh="robot0_link6_vis_6"/>
                    <geom name="robot0_g32_vis" type="mesh" contype="0" conaffinity="0" group="1" material="robot0_Union001_001_001_002_001" mesh="robot0_link6_vis_7"/>
                    <geom name="robot0_g33_vis" type="mesh" contype="0" conaffinity="0" group="1" material="robot0_Union_001_001_002_001" mesh="robot0_link6_vis_8"/>
                    <geom name="robot0_g34_vis" type="mesh" contype="0" conaffinity="0" group="1" material="robot0_Face539_002_001_002_001" mesh="robot0_link6_vis_9"/>
                    <geom name="robot0_g35_vis" type="mesh" contype="0" conaffinity="0" group="1" material="robot0_Shell_003_001_002_001" mesh="robot0_link6_vis_10"/>
                    <geom name="robot0_g36_vis" type="mesh" contype="0" conaffinity="0" group="1" material="robot0_Face374_002_001_002_001" mesh="robot0_link6_vis_11"/>
                    <geom name="robot0_g37_vis" type="mesh" contype="0" conaffinity="0" group="1" material="robot0_Face065_002_001_002_001" mesh="robot0_link6_vis_12"/>
                    <geom name="robot0_g38_vis" type="mesh" contype="0" conaffinity="0" group="1" material="robot0_Face064_002_001_002_001" mesh="robot0_link6_vis_13"/>
                    <geom name="robot0_g39_vis" type="mesh" contype="0" conaffinity="0" group="1" material="robot0_Part__Feature002_006_001_002_001" mesh="robot0_link6_vis_14"/>
                    <geom name="robot0_g40_vis" type="mesh" contype="0" conaffinity="0" group="1" material="robot0_Part__Feature001_009_001_002_001" mesh="robot0_link6_vis_15"/>
                    <geom name="robot0_g41_vis" type="mesh" contype="0" conaffinity="0" group="1" material="robot0_Shell012_002_002_001" mesh="robot0_link6_vis_16"/>
                    <geom name="robot0_link6_collision" type="mesh" rgba="0 0.5 0 1" mesh="robot0_link6"/>
                    <body name="robot0_link7" pos="0.088 0 0" quat="0.707107 0.707107 0 0">
                      <inertial pos="0 0 0.08" mass="0.5" diaginertia="0.05 0.05 0.05"/>
                      <joint name="robot0_joint7" pos="0 0 0" axis="0 0 1" limited="true" range="-2.8973 2.8973" armature="0.714286" damping="0.01" frictionloss="0.1"/>
                      <geom name="robot0_g42_vis" type="mesh" contype="0" conaffinity="0" group="1" material="robot0_Part__Mirroring004_004_002" mesh="robot0_link7_vis_0"/>
                      <geom name="robot0_g43_vis" type="mesh" contype="0" conaffinity="0" group="1" material="robot0_Part__Mirroring001_004_002" mesh="robot0_link7_vis_1"/>
                      <geom name="robot0_g44_vis" type="mesh" contype="0" conaffinity="0" group="1" material="robot0_Part__Mirroring007_004_001" mesh="robot0_link7_vis_2"/>
                      <geom name="robot0_g45_vis" type="mesh" contype="0" conaffinity="0" group="1" material="robot0_Part__Mirroring006_004_001" mesh="robot0_link7_vis_3"/>
                      <geom name="robot0_g46_vis" type="mesh" contype="0" conaffinity="0" group="1" material="robot0_Part__Mirroring005_004_001" mesh="robot0_link7_vis_4"/>
                      <geom name="robot0_g47_vis" type="mesh" contype="0" conaffinity="0" group="1" material="robot0_Part__Mirroring003_004_001" mesh="robot0_link7_vis_5"/>
                      <geom name="robot0_g48_vis" type="mesh" contype="0" conaffinity="0" group="1" material="robot0_Part__Mirroring002_004_001" mesh="robot0_link7_vis_6"/>
                      <geom name="robot0_g49_vis" type="mesh" contype="0" conaffinity="0" group="1" material="robot0_Part__Mirroring_004_001" mesh="robot0_link7_vis_7"/>
                      <geom name="robot0_link7_collision" type="mesh" rgba="0 0.5 0 1" mesh="robot0_link7"/>
                      <body name="robot0_right_hand" pos="0 0 0.1065" quat="0.923785 0 0 -0.382911">
                        <inertial pos="0 0 0" mass="0.5" diaginertia="0.05 0.05 0.05"/>
                        <camera name="robot0_eye_in_hand" pos="0.05 0 0" quat="0 0.707107 0.707107 0" fovy="75"/>
                        <body name="gripper0_right_gripper" quat="0.707107 0 0 -0.707107">
                          <inertial pos="0 0 0.17" quat="0.707107 0.707107 0 0" mass="0.3" diaginertia="0.09 0.07 0.05"/>
                          <geom name="gripper0_hand_visual" quat="0.707107 0 0 0.707107" type="mesh" contype="0" conaffinity="0" group="1" rgba="1 1 1 1" mesh="gripper0_hand_vis"/>
                          <geom name="gripper0_hand_collision" quat="0.707107 0 0 0.707107" type="mesh" rgba="0 0 0.5 1" mesh="gripper0_hand"/>
                          <site name="gripper0_ft_frame" pos="0 0 0" size="0.01" group="1" rgba="1 0 0 1"/>
                          <body name="gripper0_eef" pos="0 0 0.097">
                            <site name="gripper0_grip_site" pos="0 0 0" size="0.01" group="1" rgba="1 0 0 0.5"/>
                            <site name="gripper0_ee_x" pos="0.1 0 0" quat="0.707105 0 0.707108 0" size="0.005 0.1" group="1" type="cylinder" rgba="1 0 0 0"/>
                            <site name="gripper0_ee_y" pos="0 0.1 0" quat="0.707105 0.707108 0 0" size="0.005 0.1" group="1" type="cylinder" rgba="0 1 0 0"/>
                            <site name="gripper0_ee_z" pos="0 0 0.1" size="0.005 0.1" group="1" type="cylinder" rgba="0 0 1 0"/>
                            <site name="gripper0_grip_site_cylinder" pos="0 0 0" size="0.005 10" group="1" type="cylinder" rgba="0 1 0 0.3"/>
                          </body>
                          <body name="gripper0_leftfinger" pos="0 0 0.0524" quat="0.707107 0 0 0.707107">
                            <inertial pos="0 0 0.05" mass="0.1" diaginertia="0.01 0.01 0.005"/>
                            <joint name="gripper0_finger_joint1" pos="0 0 0" axis="0 1 0" type="slide" limited="true" range="0 0.04" armature="1" damping="100" frictionloss="1"/>
                            <geom name="gripper0_finger1_visual" type="mesh" contype="0" conaffinity="0" group="1" rgba="0.499 0.499 0.499 1" mesh="gripper0_finger_vis"/>
                            <geom name="gripper0_finger1_collision" type="mesh" contype="0" condim="4" rgba="0 0 0.5 1" mesh="gripper0_finger"/>
                            <body name="gripper0_finger_joint1_tip" pos="0 0.0085 0.056">
                              <inertial pos="0 0 0" quat="0 0 0 1" mass="0.01" diaginertia="0.01 0.01 0.01"/>
                              <geom name="gripper0_finger1_pad_collision" size="0.008 0.004 0.008" pos="0 -0.005 -0.015" quat="0 0 0 1" type="box" friction="2 0.05" solref="0.01 0.5" rgba="0 0 0.5 1"/>
                            </body>
                          </body>
                          <body name="gripper0_rightfinger" pos="0 0 0.0524" quat="0.707107 0 0 0.707107">
                            <inertial pos="0 0 0.05" mass="0.1" diaginertia="0.01 0.01 0.005"/>
                            <joint name="gripper0_finger_joint2" pos="0 0 0" axis="0 1 0" type="slide" limited="true" range="-0.04 0" armature="1" damping="100" frictionloss="1"/>
                            <geom name="gripper0_finger2_visual" quat="0 0 0 1" type="mesh" contype="0" conaffinity="0" group="1" rgba="0.499 0.499 0.499 1" mesh="gripper0_finger_vis"/>
                            <geom name="gripper0_finger2_collision" quat="0 0 0 1" type="mesh" contype="0" condim="4" rgba="0 0 0.5 1" mesh="gripper0_finger"/>
                            <body name="gripper0_finger_joint2_tip" pos="0 -0.0085 0.056">
                              <inertial pos="0 0 0" quat="0 0 0 1" mass="0.01" diaginertia="0.01 0.01 0.01"/>
                              <geom name="gripper0_finger2_pad_collision" size="0.008 0.004 0.008" pos="0 0.005 -0.015" quat="0 0 0 1" type="box" friction="2 0.05" solref="0.01 0.5" rgba="0 0 0.5 1"/>
                            </body>
                          </body>
                        </body>
                      </body>
                    </body>
                  </body>
                </body>
              </body>
            </body>
          </body>
        </body>
      </body>
      <body name="mount0_base" pos="0 0 0.01">
        <body name="mount0_controller_box">
          <inertial pos="-0.325 0 -0.38" mass="46.64" diaginertia="1.71363 1.27988 0.809981"/>
          <geom name="mount0_controller_box_col" size="0.11 0.2 0.265" pos="-0.325 0 -0.38" type="box" rgba="0.5 0.5 0 1"/>
        </body>
        <body name="mount0_pedestal_feet">
          <inertial pos="-0.1225 0 -0.758" mass="167.09" diaginertia="8.16095 9.59375 15.0785"/>
          <geom name="mount0_pedestal_feet_col" size="0.385 0.35 0.155" pos="-0.1225 0 -0.758" type="box" rgba="0.5 0.5 0 1"/>
        </body>
        <body name="mount0_torso">
          <inertial pos="0 0 0" mass="0.0001" diaginertia="1e-08 1e-08 1e-08"/>
          <geom name="mount0_torso_vis" size="0.05 0.05 0.05" pos="0 0 -0.05" type="box" contype="0" conaffinity="0" group="1" rgba="0.2 0.2 0.2 1"/>
        </body>
        <body name="mount0_pedestal">
          <inertial pos="0 0 0" quat="0.659267 -0.259505 -0.260945 0.655692" mass="60.864" diaginertia="6.0869 5.81635 4.20915"/>
          <geom name="mount0_pedestal_vis" type="mesh" contype="0" conaffinity="0" group="1" rgba="0.2 0.2 0.2 1" mesh="mount0_pedestal"/>
          <geom name="mount0_pedestal_col" size="0.18 0.31" pos="-0.02 0 -0.29" type="cylinder" rgba="0.5 0.5 0 1"/>
        </body>
      </body>
    </body>
    <body name="akita_black_bowl_1_main" pos="0 -0.1 0">
      <joint name="akita_black_bowl_1_joint0" type="free" damping="0.0005"/>
      <geom name="akita_black_bowl_1_g0" type="mesh" contype="0" conaffinity="0" group="1" friction="0.95 0.3 0.1" solref="0.001" solimp="0.998 0.998" density="100" material="akita_black_bowl_1_akita_black_bowl" mesh="akita_black_bowl_1_akita_black_bowl_vis"/>
      <geom name="akita_black_bowl_1_g1" size="0.00071 0.00992 0.01187" pos="-0.0001 0.03361 0.00939" quat="0.609901 -0.3578 -0.3578 -0.609901" type="box" friction="0.95 0.3 0.1" solref="0.001" solimp="0.998 0.998" density="100" rgba="0.8 0.8 0.8 0.3"/>
      <geom name="akita_black_bowl_1_g2" size="0.00071 0.00992 0.01187" pos="-0.01469 0.03017 0.00959" quat="0.459591 -0.426721 0.267041 0.731692" type="box" friction="0.95 0.3 0.1" solref="0.001" solimp="0.998 0.998" density="100" rgba="0.8 0.8 0.8 0.3"/>
      <geom name="akita_black_bowl_1_g3" size="0.00071 0.00992 0.01187" pos="-0.02605 0.02108 0.00975" quat="0.291721 -0.472991 0.16619 0.814592" type="box" friction="0.95 0.3 0.1" solref="0.001" solimp="0.998 0.998" density="100" rgba="0.8 0.8 0.8 0.3"/>
      <geom name="akita_black_bowl_1_g4" size="0.00071 0.00992 0.01187" pos="-0.03253 0.00793 0.00984" quat="0.10855 -0.496982 0.0565802 0.859083" type="box" friction="0.95 0.3 0.1" solref="0.001" solimp="0.998 0.998" density="100" rgba="0.8 0.8 0.8 0.3"/>
      <geom name="akita_black_bowl_1_g5" size="0.00071 0.00992 0.01187" pos="-0.03287 -0.00635 0.00984" quat="0.497612 -0.0772204 0.862464 0.0507402" type="box" friction="0.95 0.3 0.1" solref="0.001" solimp="0.998 0.998" density="100" rgba="0.8 0.8 0.8 0.3"/>
      <geom name="akita_black_bowl_1_g6" size="0.00071 0.00992 0.01187" pos="-0.02692 -0.0199 0.00984" quat="0.474079 -0.265969 0.824058 0.15949" type="box" friction="0.95 0.3 0.1" solref="0.001" solimp="0.998 0.998" density="100" rgba="0.8 0.8 0.8 0.3"/>
      <geom name="akita_black_bowl_1_g7" size="0.00071 0.00992 0.01187" pos="-0.01557 -0.02964 0.00984" quat="0.426461 -0.443361 0.743802 0.261381" type="box" friction="0.95 0.3 0.1" solref="0.001" solimp="0.998 0.998" density="100" rgba="0.8 0.8 0.8 0.3"/>
      <geom name="akita_black_bowl_1_g8" size="0.00071 0.00992 0.01187" pos="-0.00121 -0.03346 0.00984" quat="0.597279 0.357869 0.349459 -0.626949" type="box" friction="0.95 0.3 0.1" solref="0.001" solimp="0.998 0.998" density="100" rgba="0.8 0.8 0.8 0.3"/>
      <geom name="akita_black_bowl_1_g9" size="0.00071 0.00992 0.01187" pos="0.01351 -0.03063 0.00984" quat="0.722489 0.27055 0.420699 -0.477309" type="box" friction="0.95 0.3 0.1" solref="0.001" solimp="0.998 0.998" density="100" rgba="0.8 0.8 0.8 0.3"/>
      <geom name="akita_black_bowl_1_g10" size="0.00071 0.00992 0.01187" pos="0.02523 -0.02201 0.00984" quat="0.172669 -0.808937 0.308909 0.469448" type="box" friction="0.95 0.3 0.1" solref="0.001" solimp="0.998 0.998" density="100" rgba="0.8 0.8 0.8 0.3"/>
      <geom name="akita_black_bowl_1_g11" size="0.00071 0.00992 0.01187" pos="0.03222 -0.0091 0.00984" quat="0.856998 0.0654998 0.495879 -0.12397" type="box" friction="0.95 0.3 0.1" solref="0.001" solimp="0.998 0.998" density="100" rgba="0.8 0.8 0.8 0.3"/>
      <geom name="akita_black_bowl_1_g12" size="0.00071 0.00992 0.01187" pos="0.03222 -0.0091 0.00984" quat="0.856998 0.0654998 0.495879 -0.12397" type="box" friction="0.95 0.3 0.1" solref="0.001" solimp="0.998 0.998" density="100" rgba="0.8 0.8 0.8 0.3"/>
      <geom name="akita_black_bowl_1_g13" size="0.00071 0.00992 0.01187" pos="0.03348 0.00022 0.00984" quat="0.865911 -0.00473 0.50017 -0.00248" type="box" friction="0.95 0.3 0.1" solref="0.001" solimp="0.998 0.998" density="100" rgba="0.8 0.8 0.8 0.3"/>
      <geom name="akita_black_bowl_1_g14" size="0.00071 0.00992 0.01187" pos="0.03036 0.01411 0.00984" quat="0.84663 -0.11101 0.48771 0.18175" type="box" friction="0.95 0.3 0.1" solref="0.001" solimp="0.998 0.998" density="100" rgba="0.8 0.8 0.8 0.3"/>
      <geom name="akita_black_bowl_1_g15" size="0.00071 0.00992 0.01187" pos="0.02156 0.02562 0.00984" quat="0.21392 0.787241 0.36065 -0.45213" type="box" friction="0.95 0.3 0.1" solref="0.001" solimp="0.998 0.998" density="100" rgba="0.8 0.8 0.8 0.3"/>
      <geom name="akita_black_bowl_1_g16" size="0.00071 0.00992 0.01187" pos="0.01157 0.03142 0.00984" quat="0.713241 -0.2887 0.408471 0.491011" type="box" friction="0.95 0.3 0.1" solref="0.001" solimp="0.998 0.998" density="100" rgba="0.8 0.8 0.8 0.3"/>
      <geom name="akita_black_bowl_1_g17" size="0.00128 0.00934 0.01875" pos="-0.0001 0.04712 0.03367" quat="0.0904104 0.701303 0.701303 -0.0904104" type="box" friction="0.95 0.3 0.1" solref="0.001" solimp="0.998 0.998" density="100" rgba="0.8 0.8 0.8 0.3"/>
      <geom name="akita_black_bowl_1_g18" size="0.00128 0.00934 0.01875" pos="-0.01724 0.04385 0.03367" quat="0.10558 0.559299 0.819049 -0.0720899" type="box" friction="0.95 0.3 0.1" solref="0.001" solimp="0.998 0.998" density="100" rgba="0.8 0.8 0.8 0.3"/>
      <geom name="akita_black_bowl_1_g19" size="0.00128 0.00934 0.01875" pos="-0.03174 0.03483 0.03367" quat="0.11689 0.40164 0.906831 -0.0517601" type="box" friction="0.95 0.3 0.1" solref="0.001" solimp="0.998 0.998" density="100" rgba="0.8 0.8 0.8 0.3"/>
      <geom name="akita_black_bowl_1_g20" size="0.00128 0.00934 0.01875" pos="-0.04214 0.02108 0.03367" quat="0.2289 -0.12439 0.02951 0.965019" type="box" friction="0.95 0.3 0.1" solref="0.001" solimp="0.998 0.998" density="100" rgba="0.8 0.8 0.8 0.3"/>
      <geom name="akita_black_bowl_1_g21" size="0.00128 0.00934 0.01875" pos="-0.04689 0.0046 0.03367" quat="0.12768 0.04949 0.990559 -0.00638" type="box" friction="0.95 0.3 0.1" solref="0.001" solimp="0.998 0.998" density="100" rgba="0.8 0.8 0.8 0.3"/>
      <geom name="akita_black_bowl_1_g22" size="0.00128 0.00934 0.01875" pos="-0.04555 -0.01204 0.03367" quat="0.126789 0.126799 0.0163499 -0.983656" type="box" friction="0.95 0.3 0.1" solref="0.001" solimp="0.998 0.998" density="100" rgba="0.8 0.8 0.8 0.3"/>
      <geom name="akita_black_bowl_1_g23" size="0.00128 0.00934 0.01875" pos="-0.03825 -0.02751 0.03367" quat="0.121729 -0.303249 0.944296 0.0390898" type="box" friction="0.95 0.3 0.1" solref="0.001" solimp="0.998 0.998" density="100" rgba="0.8 0.8 0.8 0.3"/>
      <geom name="akita_black_bowl_1_g24" size="0.00128 0.00934 0.01875" pos="-0.02576 -0.03946 0.03367" quat="0.11249 -0.471279 0.872669 0.0607499" type="box" friction="0.95 0.3 0.1" solref="0.001" solimp="0.998 0.998" density="100" rgba="0.8 0.8 0.8 0.3"/>
      <geom name="akita_black_bowl_1_g25" size="0.00128 0.00934 0.01875" pos="-0.0101 -0.04602 0.03367" quat="0.620797 0.0997095 0.0800296 -0.773476" type="box" friction="0.95 0.3 0.1" solref="0.001" solimp="0.998 0.998" density="100" rgba="0.8 0.8 0.8 0.3"/>
      <geom name="akita_black_bowl_1_g26" size="0.00128 0.00934 0.01875" pos="0.00698 -0.0466 0.03367" quat="0.750819 0.0835199 0.0967799 -0.648019" type="box" friction="0.95 0.3 0.1" solref="0.001" solimp="0.998 0.998" density="100" rgba="0.8 0.8 0.8 0.3"/>
      <geom name="akita_black_bowl_1_g27" size="0.00128 0.00934 0.01875" pos="0.02325 -0.04098 0.03367" quat="0.0644502 -0.856513 0.500042 0.11041" type="box" friction="0.95 0.3 0.1" solref="0.001" solimp="0.998 0.998" density="100" rgba="0.8 0.8 0.8 0.3"/>
      <geom name="akita_black_bowl_1_g28" size="0.00128 0.00934 0.01875" pos="0.03631 -0.03003 0.03367" quat="0.932832 0.0434201 0.12024 -0.336871" type="box" friction="0.95 0.3 0.1" solref="0.001" solimp="0.998 0.998" density="100" rgba="0.8 0.8 0.8 0.3"/>
      <geom name="akita_black_bowl_1_g29" size="0.00128 0.00934 0.01875" pos="0.04475 -0.01475 0.03367" quat="0.0203999 -0.979087 0.15826 0.1262" type="box" friction="0.95 0.3 0.1" solref="0.001" solimp="0.998 0.998" density="100" rgba="0.8 0.8 0.8 0.3"/>
      <geom name="akita_black_bowl_1_g30" size="0.00128 0.00934 0.01875" pos="0.04708 0.00185 0.03367" quat="0.00238001 0.991623 0.0184401 -0.12782" type="box" friction="0.95 0.3 0.1" solref="0.001" solimp="0.998 0.998" density="100" rgba="0.8 0.8 0.8 0.3"/>
      <geom name="akita_black_bowl_1_g31" size="0.00128 0.00934 0.01875" pos="0.04708 0.00185 0.03367" quat="0.00238001 0.991623 0.0184401 -0.12782" type="box" friction="0.95 0.3 0.1" solref="0.001" solimp="0.998 0.998" density="100" rgba="0.8 0.8 0.8 0.3"/>
      <geom name="akita_black_bowl_1_g32" size="0.00128 0.00934 0.01875" pos="0.04341 0.01832 0.03367" quat="0.0252399 0.972287 0.195739 -0.12533" type="box" friction="0.95 0.3 0.1" solref="0.001" solimp="0.998 0.998" density="100" rgba="0.8 0.8 0.8 0.3"/>
      <geom name="akita_black_bowl_1_g33" size="0.00128 0.00934 0.01875" pos="0.03416 0.03245 0.03367" quat="0.0472901 0.921461 0.36683 -0.11878" type="box" friction="0.95 0.3 0.1" solref="0.001" solimp="0.998 0.998" density="100" rgba="0.8 0.8 0.8 0.3"/>
      <geom name="akita_black_bowl_1_g34" size="0.00128 0.00934 0.01875" pos="0.02067 0.04234 0.03367" quat="0.0675998 0.841747 0.524518 -0.1085" type="box" friction="0.95 0.3 0.1" solref="0.001" solimp="0.998 0.998" density="100" rgba="0.8 0.8 0.8 0.3"/>
      <geom name="akita_black_bowl_1_g35" size="0.00125 0.00444 0.01872" pos="0.01056 0.04592 0.03367" quat="0.0795303 0.776563 0.616932 -0.1001" type="box" friction="0.95 0.3 0.1" solref="0.001" solimp="0.998 0.998" density="100" rgba="0.8 0.8 0.8 0.3"/>
      <geom name="akita_black_bowl_1_g36" size="0.00258 0.01547 0.01617" pos="0 -0.00075 0.00417" quat="0.707107 0 0.707107 0" type="box" friction="0.95 0.3 0.1" solref="0.001" solimp="0.998 0.998" density="100" rgba="0.8 0.8 0.8 0.3"/>
      <geom name="akita_black_bowl_1_g37" size="0.00258 0.00431 0.01617" pos="0 -0.02021 0.00417" quat="0.707107 0 0.707107 0" type="box" friction="0.95 0.3 0.1" solref="0.001" solimp="0.998 0.998" density="100" rgba="0.8 0.8 0.8 0.3"/>
      <geom name="akita_black_bowl_1_g38" size="0.00258 0.00495 0.01547" pos="0.01821 0.00016 0.00417" quat="0.5 -0.5 0.5 0.5" type="box" friction="0.95 0.3 0.1" solref="0.001" solimp="0.998 0.998" density="100" rgba="0.8 0.8 0.8 0.3"/>
      <geom name="akita_black_bowl_1_g39" size="0.00258 0.00453 0.01547" pos="-0.0181 4e-05 0.00417" quat="0.5 -0.5 0.5 0.5" type="box" friction="0.95 0.3 0.1" solref="0.001" solimp="0.998 0.998" density="100" rgba="0.8 0.8 0.8 0.3"/>
      <geom name="akita_black_bowl_1_g40" size="0.00258 0.00741 0.01617" pos="0 0.0149 0.00417" quat="0 0.707107 0 -0.707107" type="box" friction="0.95 0.3 0.1" solref="0.001" solimp="0.998 0.998" density="100" rgba="0.8 0.8 0.8 0.3"/>
      <site name="akita_black_bowl_1_default_site" pos="0 0 0" size="0.002" rgba="1 0 0 0"/>
    </body>
    <body name="wine_bottle_1_main">
      <joint name="wine_bottle_1_joint0" type="free" damping="0.0005"/>
      <geom name="wine_bottle_1_g0" type="mesh" contype="0" conaffinity="0" group="1" friction="0.95 0.3 0.1" solref="0.001" solimp="0.998 0.998" density="100" material="wine_bottle_1_wine_bottle_red_main" mesh="wine_bottle_1_wine_bottle_red_main_vis"/>
      <geom name="wine_bottle_1_g1" type="mesh" contype="0" conaffinity="0" group="1" friction="0.95 0.3 0.1" solref="0.001" solimp="0.998 0.998" density="100" material="wine_bottle_1_wine_bottle_red_cork" mesh="wine_bottle_1_wine_bottle_red_cork_vis"/>
      <geom name="wine_bottle_1_g2" type="mesh" contype="0" conaffinity="0" group="1" friction="0.95 0.3 0.1" solref="0.001" solimp="0.998 0.998" density="100" material="wine_bottle_1_wine_bottle_red_logo" mesh="wine_bottle_1_wine_bottle_red_logo_vis"/>
      <geom name="wine_bottle_1_g3" size="0.01503 0.01503 0.03615" pos="0 0 0.03726" quat="0 0 0 1" type="box" friction="0.95 0.3 0.1" solref="0.001" solimp="0.998 0.998" density="100" rgba="0.8 0.8 0.8 0.3"/>
      <geom name="wine_bottle_1_g4" size="0.0052 0.0052 0.05518" pos="0 0 0.10286" quat="0 0 0 1" type="box" friction="0.95 0.3 0.1" solref="0.001" solimp="0.998 0.998" density="100" rgba="0.8 0.8 0.8 0.3"/>
      <geom name="wine_bottle_1_g5" size="0.007 0.0118 0.0118" pos="0 0 0.08109" quat="0.5 0.5 -0.5 0.5" type="box" friction="0.95 0.3 0.1" solref="0.001" solimp="0.998 0.998" density="100" rgba="0.8 0.8 0.8 0.3"/>
      <geom name="wine_bottle_1_g6" size="0.00258 0.00258 0.05518" pos="0.0045 0 0.10286" quat="0 0 0 1" type="box" friction="0.95 0.3 0.1" solref="0.001" solimp="0.998 0.998" density="100" rgba="0.8 0.8 0.8 0.3"/>
      <geom name="wine_bottle_1_g7" size="0.00258 0.00258 0.05518" pos="0.00381 -0.00246 0.10286" quat="0 0 0 1" type="box" friction="0.95 0.3 0.1" solref="0.001" solimp="0.998 0.998" density="100" rgba="0.8 0.8 0.8 0.3"/>
      <geom name="wine_bottle_1_g8" size="0.00258 0.00258 0.05518" pos="0.00223 -0.0039 0.10286" quat="0 0 0 1" type="box" friction="0.95 0.3 0.1" solref="0.001" solimp="0.998 0.998" density="100" rgba="0.8 0.8 0.8 0.3"/>
      <geom name="wine_bottle_1_g9" size="0.00258 0.00258 0.05518" pos="0.00012 -0.00478 0.10286" quat="0 0 0 1" type="box" friction="0.95 0.3 0.1" solref="0.001" solimp="0.998 0.998" density="100" rgba="0.8 0.8 0.8 0.3"/>
      <geom name="wine_bottle_1_g10" size="0.00258 0.00258 0.05518" pos="-0.00357 -0.00301 0.10286" quat="0 0.707107 0.707107 0" type="box" friction="0.95 0.3 0.1" solref="0.001" solimp="0.998 0.998" density="100" rgba="0.8 0.8 0.8 0.3"/>
      <geom name="wine_bottle_1_g11" size="0.00258 0.00258 0.05518" pos="-0.00384 -0.00096 0.10286" quat="0 0 1 0" type="box" friction="0.95 0.3 0.1" solref="0.001" solimp="0.998 0.998" density="100" rgba="0.8 0.8 0.8 0.3"/>
      <geom name="wine_bottle_1_g12" size="0.00258 0.00258 0.05518" pos="-0.00343 0.00314 0.10286" quat="0 0 0 1" type="box" friction="0.95 0.3 0.1" solref="0.001" solimp="0.998 0.998" density="100" rgba="0.8 0.8 0.8 0.3"/>
      <geom name="wine_bottle_1_g13" size="0.00258 0.00258 0.05518" pos="-0.0007 0.00424 0.10286" quat="0 0 1 0" type="box" friction="0.95 0.3 0.1" solref="0.001" solimp="0.998 0.998" density="100" rgba="0.8 0.8 0.8 0.3"/>
      <geom name="wine_bottle_1_g14" size="0.00258 0.00258 0.05518" pos="0.00272 0.00383 0.10286" quat="0 0 0 1" type="box" friction="0.95 0.3 0.1" solref="0.001" solimp="0.998 0.998" density="100" rgba="0.8 0.8 0.8 0.3"/>
      <geom name="wine_bottle_1_g15" size="0.007 0.00803 0.00803" pos="0 0 0.09305" quat="0.5 0.5 -0.5 0.5" type="box" friction="0.95 0.3 0.1" solref="0.001" solimp="0.998 0.998" density="100" rgba="0.8 0.8 0.8 0.3"/>
      <geom name="wine_bottle_1_g16" size="0.00193 0.01055 0.02979" pos="-0.0173 0 0.03331" quat="0 0 1 0" type="box" friction="0.95 0.3 0.1" solref="0.001" solimp="0.998 0.998" density="100" rgba="0.8 0.8 0.8 0.3"/>
      <geom name="wine_bottle_1_g17" size="0.00193 0.01055 0.02979" pos="0.01789 0 0.03331" quat="0 0 1 0" type="box" friction="0.95 0.3 0.1" solref="0.001" solimp="0.998 0.998" density="100" rgba="0.8 0.8 0.8 0.3"/>
      <geom name="wine_bottle_1_g18" size="0.00193 0.01055 0.02979" pos="0.00086 0.01787 0.03331" quat="0 -0.723888 -0.689918 0" type="box" friction="0.95 0.3 0.1" solref="0.001" solimp="0.998 0.998" density="100" rgba="0.8 0.8 0.8 0.3"/>
      <geom name="wine_bottle_1_g19" size="0.00193 0.01055 0.02979" pos="-0.00024 -0.01789 0.03331" quat="0 -0.711831 -0.702351 0" type="box" friction="0.95 0.3 0.1" solref="0.001" solimp="0.998 0.998" density="100" rgba="0.8 0.8 0.8 0.3"/>
      <geom name="wine_bottle_1_g20" size="0.00193 0.01055 0.02979" pos="-0.01124 -0.01392 0.03331" quat="0 -0.43119 0.902261 0" type="box" friction="0.95 0.3 0.1" solref="0.001" solimp="0.998 0.998" density="100" rgba="0.8 0.8 0.8 0.3"/>
      <geom name="wine_bottle_1_g21" size="0.00193 0.01055 0.02979" pos="-0.01071 0.01433 0.03331" quat="0 -0.894023 0.448021 0" type="box" friction="0.95 0.3 0.1" solref="0.001" solimp="0.998 0.998" density="100" rgba="0.8 0.8 0.8 0.3"/>
      <geom name="wine_bottle_1_g22" size="0.00193 0.01055 0.02979" pos="0.0121 0.01317 0.03331" quat="0 -0.915609 -0.40207 0" type="box" friction="0.95 0.3 0.1" solref="0.001" solimp="0.998 0.998" density="100" rgba="0.8 0.8 0.8 0.3"/>
      <geom name="wine_bottle_1_g23" size="0.00193 0.01055 0.02979" pos="0.01363 -0.01158 0.03331" quat="0 0.34482 0.938669 0" type="box" friction="0.95 0.3 0.1" solref="0.001" solimp="0.998 0.998" density="100" rgba="0.8 0.8 0.8 0.3"/>
      <site name="wine_bottle_1_default_site" pos="0 0 0" size="0.002" rgba="1 0 0 0"/>
    </body>
    <body name="plate_1_main">
      <joint name="plate_1_joint0" type="free" damping="0.0005"/>
      <geom name="plate_1_g0" type="mesh" contype="0" conaffinity="0" group="1" friction="0.95 0.3 0.1" solref="0.001" solimp="0.998 0.998" density="100" material="plate_1_model" mesh="plate_1_model_vis"/>
      <geom name="plate_1_g1" size="0.00222 0.02851 0.03057" pos="0 0 0.00313" quat="0.493559 0.493559 -0.506359 0.506359" type="box" friction="0.95 0.3 0.1" solref="0.001" solimp="0.998 0.998" density="100" rgba="0.8 0.8 0.8 0.3"/>
      <geom name="plate_1_g2" size="0.00254 0.01913 0.02851" pos="0 0.04828 0.00696" quat="0.705736 0.121389 0.687896 0.118319" type="box" friction="0.95 0.3 0.1" solref="0.001" solimp="0.998 0.998" density="100" rgba="0.8 0.8 0.8 0.3"/>
      <geom name="plate_1_g3" size="0.00254 0.01913 0.02851" pos="0 0.04828 0.00696" quat="0.705736 0.121389 0.687896 0.118319" type="box" friction="0.95 0.3 0.1" solref="0.001" solimp="0.998 0.998" density="100" rgba="0.8 0.8 0.8 0.3"/>
      <geom name="plate_1_g4" size="0.00254 0.01913 0.02851" pos="0.03237 0.03583 0.00696" quat="0.701142 0.360361 0.598392 -0.14306" type="box" friction="0.95 0.3 0.1" solref="0.001" solimp="0.998 0.998" density="100" rgba="0.8 0.8 0.8 0.3"/>
      <geom name="plate_1_g5" size="0.00254 0.01913 0.02851" pos="0.04818 0.00314 0.00696" quat="0.5959 0.55892 0.41899 -0.39618" type="box" friction="0.95 0.3 0.1" solref="0.001" solimp="0.998 0.998" density="100" rgba="0.8 0.8 0.8 0.3"/>
      <geom name="plate_1_g6" size="0.00254 0.01913 0.02851" pos="0.03658 -0.03152 0.00696" quat="0.675912 -0.401641 0.592241 0.17629" type="box" friction="0.95 0.3 0.1" solref="0.001" solimp="0.998 0.998" density="100" rgba="0.8 0.8 0.8 0.3"/>
      <geom name="plate_1_g7" size="0.00254 0.01913 0.02851" pos="0.0023 -0.04823 0.00696" quat="0.13507 0.69059 -0.105 -0.70272" type="box" friction="0.95 0.3 0.1" solref="0.001" solimp="0.998 0.998" density="100" rgba="0.8 0.8 0.8 0.3"/>
      <geom name="plate_1_g8" size="0.00254 0.01913 0.02851" pos="-0.03334 -0.03492 0.00696" quat="0.593389 0.15267 0.699109 -0.368549" type="box" friction="0.95 0.3 0.1" solref="0.001" solimp="0.998 0.998" density="100" rgba="0.8 0.8 0.8 0.3"/>
      <geom name="plate_1_g9" size="0.00254 0.01913 0.02851" pos="-0.04827 -0.0013 0.00696" quat="0.408271 0.407461 0.588251 -0.566791" type="box" friction="0.95 0.3 0.1" solref="0.001" solimp="0.998 0.998" density="100" rgba="0.8 0.8 0.8 0.3"/>
      <geom name="plate_1_g10" size="0.00254 0.01913 0.02851" pos="-0.03442 0.03386 0.00696" quat="0.605157 -0.153919 0.681357 0.381898" type="box" friction="0.95 0.3 0.1" solref="0.001" solimp="0.998 0.998" density="100" rgba="0.8 0.8 0.8 0.3"/>
      <site name="plate_1_default_site" pos="0 0 0" size="0.002" rgba="1 0 0 0"/>
    </body>
    <body name="plate_2_main">
      <joint name="plate_2_joint0" type="free" damping="0.0005"/>
      <geom name="plate_2_g0" type="mesh" contype="0" conaffinity="0" group="1" friction="0.95 0.3 0.1" solref="0.001" solimp="0.998 0.998" density="100" material="plate_2_model" mesh="plate_2_model_vis"/>
      <geom name="plate_2_g1" size="0.00222 0.02851 0.03057" pos="0 0 0.00313" quat="0.493559 0.493559 -0.506359 0.506359" type="box" friction="0.95 0.3 0.1" solref="0.001" solimp="0.998 0.998" density="100" rgba="0.8 0.8 0.8 0.3"/>
      <geom name="plate_2_g2" size="0.00254 0.01913 0.02851" pos="0 0.04828 0.00696" quat="0.705736 0.121389 0.687896 0.118319" type="box" friction="0.95 0.3 0.1" solref="0.001" solimp="0.998 0.998" density="100" rgba="0.8 0.8 0.8 0.3"/>
      <geom name="plate_2_g3" size="0.00254 0.01913 0.02851" pos="0 0.04828 0.00696" quat="0.705736 0.121389 0.687896 0.118319" type="box" friction="0.95 0.3 0.1" solref="0.001" solimp="0.998 0.998" density="100" rgba="0.8 0.8 0.8 0.3"/>
      <geom name="plate_2_g4" size="0.00254 0.01913 0.02851" pos="0.03237 0.03583 0.00696" quat="0.701142 0.360361 0.598392 -0.14306" type="box" friction="0.95 0.3 0.1" solref="0.001" solimp="0.998 0.998" density="100" rgba="0.8 0.8 0.8 0.3"/>
      <geom name="plate_2_g5" size="0.00254 0.01913 0.02851" pos="0.04818 0.00314 0.00696" quat="0.5959 0.55892 0.41899 -0.39618" type="box" friction="0.95 0.3 0.1" solref="0.001" solimp="0.998 0.998" density="100" rgba="0.8 0.8 0.8 0.3"/>
      <geom name="plate_2_g6" size="0.00254 0.01913 0.02851" pos="0.03658 -0.03152 0.00696" quat="0.675912 -0.401641 0.592241 0.17629" type="box" friction="0.95 0.3 0.1" solref="0.001" solimp="0.998 0.998" density="100" rgba="0.8 0.8 0.8 0.3"/>
      <geom name="plate_2_g7" size="0.00254 0.01913 0.02851" pos="0.0023 -0.04823 0.00696" quat="0.13507 0.69059 -0.105 -0.70272" type="box" friction="0.95 0.3 0.1" solref="0.001" solimp="0.998 0.998" density="100" rgba="0.8 0.8 0.8 0.3"/>
      <geom name="plate_2_g8" size="0.00254 0.01913 0.02851" pos="-0.03334 -0.03492 0.00696" quat="0.593389 0.15267 0.699109 -0.368549" type="box" friction="0.95 0.3 0.1" solref="0.001" solimp="0.998 0.998" density="100" rgba="0.8 0.8 0.8 0.3"/>
      <geom name="plate_2_g9" size="0.00254 0.01913 0.02851" pos="-0.04827 -0.0013 0.00696" quat="0.408271 0.407461 0.588251 -0.566791" type="box" friction="0.95 0.3 0.1" solref="0.001" solimp="0.998 0.998" density="100" rgba="0.8 0.8 0.8 0.3"/>
      <geom name="plate_2_g10" size="0.00254 0.01913 0.02851" pos="-0.03442 0.03386 0.00696" quat="0.605157 -0.153919 0.681357 0.381898" type="box" friction="0.95 0.3 0.1" solref="0.001" solimp="0.998 0.998" density="100" rgba="0.8 0.8 0.8 0.3"/>
      <site name="plate_2_default_site" pos="0 0 0" size="0.002" rgba="1 0 0 0"/>
    </body>
    <body name="plate_3_main">
      <joint name="plate_3_joint0" type="free" damping="0.0005"/>
      <geom name="plate_3_g0" type="mesh" contype="0" conaffinity="0" group="1" friction="0.95 0.3 0.1" solref="0.001" solimp="0.998 0.998" density="100" material="plate_3_model" mesh="plate_3_model_vis"/>
      <geom name="plate_3_g1" size="0.00222 0.02851 0.03057" pos="0 0 0.00313" quat="0.493559 0.493559 -0.506359 0.506359" type="box" friction="0.95 0.3 0.1" solref="0.001" solimp="0.998 0.998" density="100" rgba="0.8 0.8 0.8 0.3"/>
      <geom name="plate_3_g2" size="0.00254 0.01913 0.02851" pos="0 0.04828 0.00696" quat="0.705736 0.121389 0.687896 0.118319" type="box" friction="0.95 0.3 0.1" solref="0.001" solimp="0.998 0.998" density="100" rgba="0.8 0.8 0.8 0.3"/>
      <geom name="plate_3_g3" size="0.00254 0.01913 0.02851" pos="0 0.04828 0.00696" quat="0.705736 0.121389 0.687896 0.118319" type="box" friction="0.95 0.3 0.1" solref="0.001" solimp="0.998 0.998" density="100" rgba="0.8 0.8 0.8 0.3"/>
      <geom name="plate_3_g4" size="0.00254 0.01913 0.02851" pos="0.03237 0.03583 0.00696" quat="0.701142 0.360361 0.598392 -0.14306" type="box" friction="0.95 0.3 0.1" solref="0.001" solimp="0.998 0.998" density="100" rgba="0.8 0.8 0.8 0.3"/>
      <geom name="plate_3_g5" size="0.00254 0.01913 0.02851" pos="0.04818 0.00314 0.00696" quat="0.5959 0.55892 0.41899 -0.39618" type="box" friction="0.95 0.3 0.1" solref="0.001" solimp="0.998 0.998" density="100" rgba="0.8 0.8 0.8 0.3"/>
      <geom name="plate_3_g6" size="0.00254 0.01913 0.02851" pos="0.03658 -0.03152 0.00696" quat="0.675912 -0.401641 0.592241 0.17629" type="box" friction="0.95 0.3 0.1" solref="0.001" solimp="0.998 0.998" density="100" rgba="0.8 0.8 0.8 0.3"/>
      <geom name="plate_3_g7" size="0.00254 0.01913 0.02851" pos="0.0023 -0.04823 0.00696" quat="0.13507 0.69059 -0.105 -0.70272" type="box" friction="0.95 0.3 0.1" solref="0.001" solimp="0.998 0.998" density="100" rgba="0.8 0.8 0.8 0.3"/>
      <geom name="plate_3_g8" size="0.00254 0.01913 0.02851" pos="-0.03334 -0.03492 0.00696" quat="0.593389 0.15267 0.699109 -0.368549" type="box" friction="0.95 0.3 0.1" solref="0.001" solimp="0.998 0.998" density="100" rgba="0.8 0.8 0.8 0.3"/>
      <geom name="plate_3_g9" size="0.00254 0.01913 0.02851" pos="-0.04827 -0.0013 0.00696" quat="0.408271 0.407461 0.588251 -0.566791" type="box" friction="0.95 0.3 0.1" solref="0.001" solimp="0.998 0.998" density="100" rgba="0.8 0.8 0.8 0.3"/>
      <geom name="plate_3_g10" size="0.00254 0.01913 0.02851" pos="-0.03442 0.03386 0.00696" quat="0.605157 -0.153919 0.681357 0.381898" type="box" friction="0.95 0.3 0.1" solref="0.001" solimp="0.998 0.998" density="100" rgba="0.8 0.8 0.8 0.3"/>
      <site name="plate_3_default_site" pos="0 0 0" size="0.002" rgba="1 0 0 0"/>
    </body>
    <body name="wooden_cabinet_1_main" pos="0.00700691 -0.286694 0.905" quat="0 0 0 1">
      <site name="wooden_cabinet_1_default_site" pos="0 0 0" size="0.002" rgba="1 0 0 0"/>
      <body name="wooden_cabinet_1_base">
        <geom name="wooden_cabinet_1_g0" type="mesh" contype="0" conaffinity="0" group="1" friction="0.95 0.3 0.1" solref="0.001" solimp="0.998 0.998" density="100" material="wooden_cabinet_1_wooden_cabinet_base" mesh="wooden_cabinet_1_wooden_cabinet_base_vis"/>
        <geom name="wooden_cabinet_1_g1" size="0.00193 0.10453 0.11106" pos="0.00397 0.10954 0.1135" quat="0.499879 -0.501039 -0.500119 0.498959" type="box" friction="0.95 0.3 0.1" solref="0.001" solimp="0.998 0.998" density="100" rgba="0.8 0.8 0.8 0.3"/>
        <geom name="wooden_cabinet_1_g2" size="0.00199 0.0896 0.12277" pos="0.00405 0.01635 0.00686" quat="0.707921 0.000650001 0.706291 -0.000650001" type="box" friction="0.95 0.3 0.1" solref="0.001" solimp="0.998 0.998" density="100" rgba="0.8 0.8 0.8 0.3"/>
        <geom name="wooden_cabinet_1_g3" size="0.00517 0.09542 0.10584" pos="-0.11216 0.01625 0.11426" quat="0 0 1 0" type="box" friction="0.95 0.3 0.1" solref="0.001" solimp="0.998 0.998" density="100" rgba="0.8 0.8 0.8 0.3"/>
        <geom name="wooden_cabinet_1_g4" size="0.00517 0.09542 0.10584" pos="0.11898 0.01625 0.11426" quat="0 1 0 0" type="box" friction="0.95 0.3 0.1" solref="0.001" solimp="0.998 0.998" density="100" rgba="0.8 0.8 0.8 0.3"/>
        <geom name="wooden_cabinet_1_g5" size="0.00231 0.10584 0.11912" pos="0.00211 0.10938 0.11426" quat="0.49997 0.49997 -0.50003 -0.50003" type="box" friction="0.95 0.3 0.1" solref="0.001" solimp="0.998 0.998" density="100" rgba="0.8 0.8 0.8 0.3"/>
        <geom name="wooden_cabinet_1_g6" size="0.00085 0.08935 0.11168" pos="0.00376 0.01868 0.14935" quat="0.707921 0.000650001 0.706291 -0.000650001" type="box" friction="0.95 0.3 0.1" solref="0.001" solimp="0.998 0.998" density="100" rgba="0.8 0.8 0.8 0.3"/>
        <geom name="wooden_cabinet_1_g7" size="0.00085 0.08935 0.11168" pos="0.00408 0.01868 0.00933" quat="0.000650001 -0.707921 0.000650001 0.706291" type="box" friction="0.95 0.3 0.1" solref="0.001" solimp="0.998 0.998" density="100" rgba="0.8 0.8 0.8 0.3"/>
        <geom name="wooden_cabinet_1_g8" size="0.00085 0.08935 0.11168" pos="0.00392 0.01868 0.07928" quat="0.707921 0.000650001 0.706291 -0.000650001" type="box" friction="0.95 0.3 0.1" solref="0.001" solimp="0.998 0.998" density="100" rgba="0.8 0.8 0.8 0.3"/>
        <geom name="wooden_cabinet_1_g9" size="0.00142 0.09409 0.12729" pos="0.00394 0.01577 0.22157" quat="0.707107 0 0.707107 0" type="box" friction="0.95 0.3 0.1" solref="0.001" solimp="0.998 0.998" density="100" rgba="0.8 0.8 0.8 0.3"/>
        <site name="wooden_cabinet_1_top_side" pos="0.00354 0.01567 0.22152" size="0.12534 0.09438 0.00147" type="box" rgba="0.8 0.8 0 0"/>
        <body name="wooden_cabinet_1_cabinet_top">
          <inertial pos="0 0 0" mass="3" diaginertia="1 1 1"/>
          <joint name="wooden_cabinet_1_top_level" pos="0 0 0" axis="0 1 0" type="slide" limited="true" range="-0.16 0.01" damping="50"/>
          <geom name="wooden_cabinet_1_g10" type="mesh" contype="0" conaffinity="0" group="1" friction="0.95 0.3 0.1" solref="0.001" solimp="0.998 0.998" density="100" material="wooden_cabinet_1_wooden_cabinet_top" mesh="wooden_cabinet_1_wooden_cabinet_top_vis"/>
          <geom name="wooden_cabinet_1_g11" size="0.00271 0.03427 0.10934" pos="0.00334 -0.07524 0.18309" quat="0.5 0.5 -0.5 -0.5" type="box" friction="0.95 0.3 0.1" solref="0.001" solimp="0.998 0.998" density="100" rgba="0.8 0.8 0.8 0.3"/>
          <geom name="wooden_cabinet_1_g12" size="0.00356 0.03214 0.10679" pos="0.00334 -0.06839 0.18358" quat="0.5 0.5 0.5 0.5" type="box" friction="0.95 0.3 0.1" solref="0.001" solimp="0.998 0.998" density="100" rgba="0.8 0.8 0.8 0.3"/>
          <geom name="wooden_cabinet_1_g13" size="0.00356 0.03214 0.10679" pos="0.00334 0.09077 0.18358" quat="0.5 0.5 0.5 0.5" type="box" friction="0.95 0.3 0.1" solref="0.001" solimp="0.998 0.998" density="100" rgba="0.8 0.8 0.8 0.3"/>
          <geom name="wooden_cabinet_1_g14" size="0.00241 0.03165 0.08148" pos="-0.10191 0.01105 0.18358" quat="0.707106 0.707106 -0.00114999 -0.00114999" type="box" friction="0.95 0.3 0.1" solref="0.001" solimp="0.998 0.998" density="100" rgba="0.8 0.8 0.8 0.3"/>
          <geom name="wooden_cabinet_1_g15" size="0.00241 0.03133 0.08148" pos="0.10894 0.01105 0.18358" quat="0.707106 0.707106 -0.00114999 -0.00114999" type="box" friction="0.95 0.3 0.1" solref="0.001" solimp="0.998 0.998" density="100" rgba="0.8 0.8 0.8 0.3"/>
          <geom name="wooden_cabinet_1_g16" size="0.00401 0.08095 0.10696" pos="0.00348 0.01048 0.15514" quat="0.707107 0 0.707107 0" type="box" friction="0.95 0.3 0.1" solref="0.001" solimp="0.998 0.998" density="100" rgba="0.8 0.8 0.8 0.3"/>
          <geom name="wooden_cabinet_1_g17" type="mesh" contype="0" conaffinity="0" group="1" friction="0.95 0.3 0.1" solref="0.001" solimp="0.998 0.998" density="100" material="wooden_cabinet_1_wooden_cabinet_top_handle" mesh="wooden_cabinet_1_wooden_cabinet_top_handle_vis"/>
          <geom name="wooden_cabinet_1_g18" size="0.0077 0.00817 0.04445" pos="-0.00278 -0.10161 0.18393" quat="0.5 0.5 -0.5 -0.5" type="box" friction="0.95 0.3 0.1" solref="0.001" solimp="0.998 0.998" density="100" rgba="0.8 0.8 0.8 0.3"/>
          <geom name="wooden_cabinet_1_g19" size="0.00507 0.00552 0.01057" pos="0.02916 -0.08348 0.18393" quat="0.707107 0.707107 0 0" type="box" friction="0.95 0.3 0.1" solref="0.001" solimp="0.998 0.998" density="100" rgba="0.8 0.8 0.8 0.3"/>
          <geom name="wooden_cabinet_1_g20" size="0.00507 0.0056 0.01057" pos="-0.0356 -0.08348 0.18393" quat="0.707107 0.707107 0 0" type="box" friction="0.95 0.3 0.1" solref="0.001" solimp="0.998 0.998" density="100" rgba="0.8 0.8 0.8 0.3"/>
          <site name="wooden_cabinet_1_top_region" pos="0.00328 0.01128 0.18563" quat="0.707107 0 0.707107 0" size="0.02993 0.07561 0.10224" type="box" rgba="0.8 0.8 0.8 0"/>
        </body>
        <body name="wooden_cabinet_1_cabinet_middle">
          <inertial pos="0 0 0" mass="3" diaginertia="1 1 1"/>
          <joint name="wooden_cabinet_1_middle_level" pos="0 0 0" axis="0 1 0" type="slide" limited="true" range="-0.16 0.01" damping="50"/>
          <geom name="wooden_cabinet_1_g21" type="mesh" contype="0" conaffinity="0" group="1" friction="0.95 0.3 0.1" solref="0.001" solimp="0.998 0.998" density="100" material="wooden_cabinet_1_wooden_cabinet_middle" mesh="wooden_cabinet_1_wooden_cabinet_middle_vis"/>
          <geom name="wooden_cabinet_1_g22" size="0.00271 0.03427 0.10934" pos="0.00334 -0.07524 0.11338" quat="0.5 0.5 -0.5 -0.5" type="box" friction="0.95 0.3 0.1" solref="0.001" solimp="0.998 0.998" density="100" rgba="0.8 0.8 0.8 0.3"/>
          <geom name="wooden_cabinet_1_g23" size="0.00356 0.03214 0.10679" pos="0.00334 0.09077 0.11387" quat="0.5 0.5 0.5 0.5" type="box" friction="0.95 0.3 0.1" solref="0.001" solimp="0.998 0.998" density="100" rgba="0.8 0.8 0.8 0.3"/>
          <geom name="wooden_cabinet_1_g24" size="0.00356 0.03214 0.10679" pos="0.00334 -0.06839 0.11387" quat="0.5 0.5 0.5 0.5" type="box" friction="0.95 0.3 0.1" solref="0.001" solimp="0.998 0.998" density="100" rgba="0.8 0.8 0.8 0.3"/>
          <geom name="wooden_cabinet_1_g25" size="0.00241 0.03133 0.08148" pos="0.10894 0.01105 0.11387" quat="0.707106 0.707106 -0.00114999 -0.00114999" type="box" friction="0.95 0.3 0.1" solref="0.001" solimp="0.998 0.998" density="100" rgba="0.8 0.8 0.8 0.3"/>
          <geom name="wooden_cabinet_1_g26" size="0.00241 0.03165 0.08148" pos="-0.10191 0.01105 0.11387" quat="0.707106 0.707106 -0.00114999 -0.00114999" type="box" friction="0.95 0.3 0.1" solref="0.001" solimp="0.998 0.998" density="100" rgba="0.8 0.8 0.8 0.3"/>
          <geom name="wooden_cabinet_1_g27" size="0.00401 0.08095 0.10696" pos="0.00348 0.01048 0.08543" quat="0.707107 0 0.707107 0" type="box" friction="0.95 0.3 0.1" solref="0.001" solimp="0.998 0.998" density="100" rgba="0.8 0.8 0.8 0.3"/>
          <geom name="wooden_cabinet_1_g28" type="mesh" contype="0" conaffinity="0" group="1" friction="0.95 0.3 0.1" solref="0.001" solimp="0.998 0.998" density="100" material="wooden_cabinet_1_wooden_cabinet_middle_handle" mesh="wooden_cabinet_1_wooden_cabinet_middle_handle_vis"/>
          <geom name="wooden_cabinet_1_g29" size="0.0077 0.00817 0.04445" pos="-0.00278 -0.10161 0.11041" quat="0.5 0.5 -0.5 -0.5" type="box" friction="0.95 0.3 0.1" solref="0.001" solimp="0.998 0.998" density="100" rgba="0.8 0.8 0.8 0.3"/>
          <geom name="wooden_cabinet_1_g30" size="0.00507 0.00552 0.01057" pos="0.02916 -0.08348 0.11041" quat="0.707107 0.707107 0 0" type="box" friction="0.95 0.3 0.1" solref="0.001" solimp="0.998 0.998" density="100" rgba="0.8 0.8 0.8 0.3"/>
          <geom name="wooden_cabinet_1_g31" size="0.00507 0.0056 0.01057" pos="-0.0356 -0.08348 0.11041" quat="0.707107 0.707107 0 0" type="box" friction="0.95 0.3 0.1" solref="0.001" solimp="0.998 0.998" density="100" rgba="0.8 0.8 0.8 0.3"/>
          <site name="wooden_cabinet_1_middle_region" pos="0.00328 0.01128 0.1169" quat="0.707107 0 0.707107 0" size="0.02993 0.07561 0.10224" type="box" rgba="0.8 0.8 0.8 0"/>
        </body>
        <body name="wooden_cabinet_1_cabinet_bottom">
          <inertial pos="0 0 0" mass="3" diaginertia="1 1 1"/>
          <joint name="wooden_cabinet_1_bottom_level" pos="0 0 0" axis="0 1 0" type="slide" limited="true" range="-0.16 0.01" damping="50"/>
          <geom name="wooden_cabinet_1_g32" type="mesh" contype="0" conaffinity="0" group="1" friction="0.95 0.3 0.1" solref="0.001" solimp="0.998 0.998" density="100" material="wooden_cabinet_1_wooden_cabinet_bottom" mesh="wooden_cabinet_1_wooden_cabinet_bottom_vis"/>
          <geom name="wooden_cabinet_1_g33" size="0.00271 0.03427 0.10934" pos="0.00334 -0.07524 0.04476" quat="0.5 0.5 -0.5 -0.5" type="box" friction="0.95 0.3 0.1" solref="0.001" solimp="0.998 0.998" density="100" rgba="0.8 0.8 0.8 0.3"/>
          <geom name="wooden_cabinet_1_g34" size="0.00356 0.03214 0.10679" pos="0.00334 0.09077 0.04525" quat="0.5 0.5 0.5 0.5" type="box" friction="0.95 0.3 0.1" solref="0.001" solimp="0.998 0.998" density="100" rgba="0.8 0.8 0.8 0.3"/>
          <geom name="wooden_cabinet_1_g35" size="0.00356 0.03214 0.10679" pos="0.00334 -0.06839 0.04525" quat="0.5 0.5 0.5 0.5" type="box" friction="0.95 0.3 0.1" solref="0.001" solimp="0.998 0.998" density="100" rgba="0.8 0.8 0.8 0.3"/>
          <geom name="wooden_cabinet_1_g36" size="0.00241 0.03133 0.08148" pos="0.10894 0.01105 0.04525" quat="0.707106 0.707106 -0.00114999 -0.00114999" type="box" friction="0.95 0.3 0.1" solref="0.001" solimp="0.998 0.998" density="100" rgba="0.8 0.8 0.8 0.3"/>
          <geom name="wooden_cabinet_1_g37" size="0.00241 0.03165 0.08148" pos="-0.10191 0.01105 0.04525" quat="0.707106 0.707106 -0.00114999 -0.00114999" type="box" friction="0.95 0.3 0.1" solref="0.001" solimp="0.998 0.998" density="100" rgba="0.8 0.8 0.8 0.3"/>
          <geom name="wooden_cabinet_1_g38" size="0.00401 0.08095 0.10696" pos="0.00348 0.01048 0.01682" quat="0.707107 0 0.707107 0" type="box" friction="0.95 0.3 0.1" solref="0.001" solimp="0.998 0.998" density="100" rgba="0.8 0.8 0.8 0.3"/>
          <geom name="wooden_cabinet_1_g39" type="mesh" contype="0" conaffinity="0" group="1" friction="0.95 0.3 0.1" solref="0.001" solimp="0.998 0.998" density="100" material="wooden_cabinet_1_wooden_cabinet_bottom_handle" mesh="wooden_cabinet_1_wooden_cabinet_bottom_handle_vis"/>
          <geom name="wooden_cabinet_1_g40" size="0.0077 0.00817 0.04445" pos="-0.00278 -0.10161 0.04114" quat="0.5 0.5 -0.5 -0.5" type="box" friction="0.95 0.3 0.1" solref="0.001" solimp="0.998 0.998" density="100" rgba="0.8 0.8 0.8 0.3"/>
          <geom name="wooden_cabinet_1_g41" size="0.00507 0.00552 0.01057" pos="0.02916 -0.08348 0.04114" quat="0.707107 0.707107 0 0" type="box" friction="0.95 0.3 0.1" solref="0.001" solimp="0.998 0.998" density="100" rgba="0.8 0.8 0.8 0.3"/>
          <geom name="wooden_cabinet_1_g42" size="0.00507 0.0056 0.01057" pos="-0.0356 -0.08348 0.04114" quat="0.707107 0.707107 0 0" type="box" friction="0.95 0.3 0.1" solref="0.001" solimp="0.998 0.998" density="100" rgba="0.8 0.8 0.8 0.3"/>
          <site name="wooden_cabinet_1_bottom_region" pos="0.00328 0.01128 0.04701" quat="0.707107 0 0.707107 0" size="0.02993 0.07561 0.10224" type="box" rgba="0.8 0.8 0.8 0"/>
        </body>
      </body>
    </body>
  </worldbody>

  <actuator>
    <general name="robot0_torq_j1" joint="robot0_joint1" ctrllimited="true" ctrlrange="-80 80"/>
    <general name="robot0_torq_j2" joint="robot0_joint2" ctrllimited="true" ctrlrange="-80 80"/>
    <general name="robot0_torq_j3" joint="robot0_joint3" ctrllimited="true" ctrlrange="-80 80"/>
    <general name="robot0_torq_j4" joint="robot0_joint4" ctrllimited="true" ctrlrange="-80 80"/>
    <general name="robot0_torq_j5" joint="robot0_joint5" ctrllimited="true" ctrlrange="-80 80"/>
    <general name="robot0_torq_j6" joint="robot0_joint6" ctrllimited="true" ctrlrange="-12 12"/>
    <general name="robot0_torq_j7" joint="robot0_joint7" ctrllimited="true" ctrlrange="-12 12"/>
    <general name="gripper0_gripper_finger_joint1" joint="gripper0_finger_joint1" ctrllimited="true" ctrlrange="0 0.04" forcelimited="true" forcerange="-20 20" biastype="affine" gainprm="1000" biasprm="0 -1000"/>
    <general name="gripper0_gripper_finger_joint2" joint="gripper0_finger_joint2" ctrllimited="true" ctrlrange="-0.04 0" forcelimited="true" forcerange="-20 20" biastype="affine" gainprm="1000" biasprm="0 -1000"/>
  </actuator>

  <sensor>
    <force site="gripper0_ft_frame" name="gripper0_force_ee"/>
    <torque site="gripper0_ft_frame" name="gripper0_torque_ee"/>
  </sensor>
</mujoco>
